Workbook
Name 지출대분류: '(필수)설정 시트'!$E$41:$E$50

Sheet 2026
B1: 2026 | E1: 연 총 수입 | G1: 연 총 저축/현금 | I1: 연 총 지출
E3: =P31 | G3: =P32 | I3: =P33
B30: 1년 총 비용 | D30: 1월 | E30: 2월 | F30: 3월 | G30: 4월 | H30: 5월 | I30: 6월 | J30: 7월 | K30: 8월 | L30: 9월 | M30: 10월 | N30: 11월 | O30: 12월 | P30: 최종금액
B31: 총 수입 | D31: ='1월'!$F$3 | E31: ='2월'!$F$3 | F31: ='3월'!$F$3 | G31: ='4월'!$F$3 | H31: ='5월'!$F$3 | I31: ='6월'!$F$3 | J31: ='7월'!$F$3 | K31: ='8월'!$F$3 | L31: ='9월'!$F$3 | M31: ='10월'!$F$3 | N31: ='11월'!$F$3 | O31: ='12월'!$F$3 | P31: =SUM(D31:O31)
B32: 총 저축 | D32: ='1월'!$H$3 | E32: ='2월'!$H$3 | F32: ='3월'!$H$3 | G32: ='4월'!$H$3 | H32: ='5월'!$H$3 | I32: ='6월'!$H$3 | J32: ='7월'!$H$3 | K32: ='8월'!$H$3 | L32: ='9월'!$H$3 | M32: ='10월'!$H$3 | N32: ='11월'!$H$3 | O32: ='12월'!$H$3 | P32: =SUM(D32:O32)
B33: 총 지출 | D33: ='1월'!$C$7 | E33: ='2월'!$C$7 | F33: ='3월'!$C$7 | G33: ='4월'!$C$7 | H33: ='5월'!$C$7 | I33: ='6월'!$C$7 | J33: ='7월'!$C$7 | K33: ='8월'!$C$7 | L33: ='9월'!$C$7 | M33: ='10월'!$C$7 | N33: ='11월'!$C$7 | O33: ='12월'!$C$7 | P33: =SUM(D33:O33)
B34: 총 잉여금액 | D34: ='1월'!$L$3 | E34: ='2월'!$L$3 | F34: ='3월'!$L$3 | G34: ='4월'!$L$3 | H34: ='5월'!$L$3 | I34: ='6월'!$L$3 | J34: ='7월'!$L$3 | K34: ='8월'!$L$3 | L34: ='9월'!$L$3 | M34: ='10월'!$L$3 | N34: ='11월'!$L$3 | O34: ='12월'!$L$3 | P34: =SUM(D34:O34)
B35: ='(필수)설정 시트'!E41 | D35: ='1월'!$Q$16 | E35: ='2월'!$Q$16 | F35: ='3월'!$Q$16 | G35: ='4월'!$Q$16 | H35: ='5월'!$Q$16 | I35: ='6월'!$Q$16 | J35: ='7월'!$Q$16 | K35: ='8월'!$Q$16 | L35: ='9월'!$Q$16 | M35: ='10월'!$Q$16 | N35: ='11월'!$Q$16 | O35: ='12월'!$Q$16 | P35: =SUM(D35:O35)
B36: ='(필수)설정 시트'!E42 | D36: ='1월'!$Q$23 | E36: ='2월'!$Q$23 | F36: ='3월'!$Q$23 | G36: ='4월'!$Q$23 | H36: ='5월'!$Q$23 | I36: ='6월'!$Q$23 | J36: ='7월'!$Q$23 | K36: ='8월'!$Q$23 | L36: ='9월'!$Q$23 | M36: ='10월'!$Q$23 | N36: ='11월'!$Q$23 | O36: ='12월'!$Q$23 | P36: =SUM(D36:O36)
B37: ='(필수)설정 시트'!E43 | D37: ='1월'!$Q$31 | E37: ='2월'!$Q$31 | F37: ='3월'!$Q$31 | G37: ='4월'!$Q$31 | H37: ='5월'!$Q$31 | I37: ='6월'!$Q$31 | J37: ='7월'!$Q$31 | K37: ='8월'!$Q$31 | L37: ='9월'!$Q$31 | M37: ='10월'!$Q$31 | N37: ='11월'!$Q$31 | O37: ='12월'!$Q$31 | P37: =SUM(D37:O37)
B38: ='(필수)설정 시트'!E44 | D38: ='1월'!$Q$38 | E38: ='2월'!$Q$38 | F38: ='3월'!$Q$38 | G38: ='4월'!$Q$38 | H38: ='5월'!$Q$38 | I38: ='6월'!$Q$38 | J38: ='7월'!$Q$38 | K38: ='8월'!$Q$38 | L38: ='9월'!$Q$38 | M38: ='10월'!$Q$38 | N38: ='11월'!$Q$38 | O38: ='12월'!$Q$38 | P38: =SUM(D38:O38)
B39: ='(필수)설정 시트'!E45 | D39: ='1월'!$Q$45 | E39: ='2월'!$Q$45 | F39: ='3월'!$Q$45 | G39: ='4월'!$Q$45 | H39: ='5월'!$Q$45 | I39: ='6월'!$Q$45 | J39: ='7월'!$Q$45 | K39: ='8월'!$Q$45 | L39: ='9월'!$Q$45 | M39: ='10월'!$Q$45 | N39: ='11월'!$Q$45 | O39: ='12월'!$Q$45 | P39: =SUM(D39:O39)
B40: ='(필수)설정 시트'!E46 | D40: ='1월'!$U$12 | E40: ='2월'!$U$12 | F40: ='3월'!$U$12 | G40: ='4월'!$U$12 | H40: ='5월'!$U$12 | I40: ='6월'!$U$12 | J40: ='7월'!$U$12 | K40: ='8월'!$U$12 | L40: ='9월'!$U$12 | M40: ='10월'!$U$12 | N40: ='11월'!$U$12 | O40: ='12월'!$U$12 | P40: =SUM(D40:O40)
B41: ='(필수)설정 시트'!E47 | D41: ='1월'!$U$20 | E41: ='2월'!$U$20 | F41: ='3월'!$U$20 | G41: ='4월'!$U$20 | H41: ='5월'!$U$20 | I41: ='6월'!$U$20 | J41: ='7월'!$U$20 | K41: ='8월'!$U$20 | L41: ='9월'!$U$20 | M41: ='10월'!$U$20 | N41: ='11월'!$U$20 | O41: ='12월'!$U$20 | P41: =SUM(D41:O41)
B42: ='(필수)설정 시트'!E48 | D42: ='1월'!$U$27 | E42: ='2월'!$U$27 | F42: ='3월'!$U$27 | G42: ='4월'!$U$27 | H42: ='5월'!$U$27 | I42: ='6월'!$U$27 | J42: ='7월'!$U$27 | K42: ='8월'!$U$27 | L42: ='9월'!$U$27 | M42: ='10월'!$U$27 | N42: ='11월'!$U$27 | O42: ='12월'!$U$27 | P42: =SUM(D42:O42)
B43: ='(필수)설정 시트'!E49 | D43: ='1월'!$U$34 | E43: ='2월'!$U$34 | F43: ='3월'!$U$34 | G43: ='4월'!$U$34 | H43: ='5월'!$U$34 | I43: ='6월'!$U$34 | J43: ='7월'!$U$34 | K43: ='8월'!$U$34 | L43: ='9월'!$U$34 | M43: ='10월'!$U$34 | N43: ='11월'!$U$34 | O43: ='12월'!$U$34 | P43: =SUM(D43:O43)
B44: ='(필수)설정 시트'!E50 | D44: ='1월'!$U$41 | E44: ='2월'!$U$41 | F44: ='3월'!$U$41 | G44: ='4월'!$U$41 | H44: ='5월'!$U$41 | I44: ='6월'!$U$41 | J44: ='7월'!$U$41 | K44: ='8월'!$U$41 | L44: ='9월'!$U$41 | M44: ='10월'!$U$41 | N44: ='11월'!$U$41 | O44: ='12월'!$U$41 | P44: =SUM(D44:O44)

Sheet 1월
D1: 1
B2: ='(필수)설정 시트'!B2 | F2: 총 수입 | H2: 총 저축 | J2: 총 지출 비용 | L2: 남은 잔액(부수입 제외)
F3: =C6 | H3: =C8 | J3: =C7 | L3: =(C6-E18)-C7-C8
H4: 항목 변경 시 데이터 확인 규칙 변경 필요
B5: 분류 | C5: 금액 | D5: 결제수단 | E5: 금액 | G5: 날짜[숫자만 입력] | H5: 대분류 | I5: 소분류 | J5: 금액 | K5: 결제수단 | L5: 세부사항 | M5: 남은 잔액 | O5: 대분류 | P5: 소분류 | Q5: 지출금액 | S5: 대분류 | T5: 소분류 | U5: 지출금액 | W5: 일 | X5: 월 | Y5: 화 | Z5: 수 | AA5: 목 | AB5: 금 | AC5: 토
B6: 총 수입 | C6: =E20 | M6: =$E$20-J6 | O6: ='(필수)설정 시트'!E41 | P6: 📱통신비 | Q6: =SUMIF($I$6:$I$56,P6,$J$6:$J$56) | S6: ='(필수)설정 시트'!E46 | T6: 👕의류 | U6: =SUMIF($I$6:$I$56,T6,$J$6:$J$56) | W6: =IF( (COLUMN()-COLUMN($W$6)+2) + 7*INT((ROW()-ROW($W$6))/3) - WEEKDAY(DATE('(필수)설정 시트'!$B$2, $D$1, 1), 1) <= 0, "", IF( (COLUMN()-COLUMN($W$6)+2) + 7*INT((ROW()-ROW($W$6))/3) - WEEKDAY(DATE('(필수)설정 시트'!$B$2, $D$1, 1), 1) > DAY(EOMONTH(DATE('(필수)설정 시트'!$B$2, $D$1, 1), 0)), "", TEXT( DATE('(필수)설정 시트'!$B$2, $D$1, 1) + (COLUMN()-COLUMN($W$6)+2) + 7*INT((ROW()-ROW($W$6))/3) - WEEKDAY(DATE('(필수)설정 시트'!$B$2, $D$1, 1), 1) - 1, "d" ) ) ) | X6: =IF( (COLUMN()-COLUMN($W$6)+2) + 7*INT((ROW()-ROW($W$6))/3) - WEEKDAY(DATE('(필수)설정 시트'!$B$2, $D$1, 1), 1) <= 0, "", IF( (COLUMN()-COLUMN($W$6)+2) + 7*INT((ROW()-ROW($W$6))/3) - WEEKDAY(DATE('(필수)설정 시트'!$B$2, $D$1, 1), 1) > DAY(EOMONTH(DATE('(필수)설정 시트'!$B$2, $D$1, 1), 0)), "", TEXT( DATE('(필수)설정 시트'!$B$2, $D$1, 1) + (COLUMN()-COLUMN($W$6)+2) + 7*INT((ROW()-ROW($W$6))/3) - WEEKDAY(DATE('(필수)설정 시트'!$B$2, $D$1, 1), 1) - 1, "d" ) ) ) | Y6: =IF( (COLUMN()-COLUMN($W$6)+2) + 7*INT((ROW()-ROW($W$6))/3) - WEEKDAY(DATE('(필수)설정 시트'!$B$2, $D$1, 1), 1) <= 0, "", IF( (COLUMN()-COLUMN($W$6)+2) + 7*INT((ROW()-ROW($W$6))/3) - WEEKDAY(DATE('(필수)설정 시트'!$B$2, $D$1, 1), 1) > DAY(EOMONTH(DATE('(필수)설정 시트'!$B$2, $D$1, 1), 0)), "", TEXT( DATE('(필수)설정 시트'!$B$2, $D$1, 1) + (COLUMN()-COLUMN($W$6)+2) + 7*INT((ROW()-ROW($W$6))/3) - WEEKDAY(DATE('(필수)설정 시트'!$B$2, $D$1, 1), 1) - 1, "d" ) ) ) | Z6: =IF( (COLUMN()-COLUMN($W$6)+2) + 7*INT((ROW()-ROW($W$6))/3) - WEEKDAY(DATE('(필수)설정 시트'!$B$2, $D$1, 1), 1) <= 0, "", IF( (COLUMN()-COLUMN($W$6)+2) + 7*INT((ROW()-ROW($W$6))/3) - WEEKDAY(DATE('(필수)설정 시트'!$B$2, $D$1, 1), 1) > DAY(EOMONTH(DATE('(필수)설정 시트'!$B$2, $D$1, 1), 0)), "", TEXT( DATE('(필수)설정 시트'!$B$2, $D$1, 1) + (COLUMN()-COLUMN($W$6)+2) + 7*INT((ROW()-ROW($W$6))/3) - WEEKDAY(DATE('(필수)설정 시트'!$B$2, $D$1, 1), 1) - 1, "d" ) ) ) | AA6: =IF( (COLUMN()-COLUMN($W$6)+2) + 7*INT((ROW()-ROW($W$6))/3) - WEEKDAY(DATE('(필수)설정 시트'!$B$2, $D$1, 1), 1) <= 0, "", IF( (COLUMN()-COLUMN($W$6)+2) + 7*INT((ROW()-ROW($W$6))/3) - WEEKDAY(DATE('(필수)설정 시트'!$B$2, $D$1, 1), 1) > DAY(EOMONTH(DATE('(필수)설정 시트'!$B$2, $D$1, 1), 0)), "", TEXT( DATE('(필수)설정 시트'!$B$2, $D$1, 1) + (COLUMN()-COLUMN($W$6)+2) + 7*INT((ROW()-ROW($W$6))/3) - WEEKDAY(DATE('(필수)설정 시트'!$B$2, $D$1, 1), 1) - 1, "d" ) ) ) | AB6: =IF( (COLUMN()-COLUMN($W$6)+2) + 7*INT((ROW()-ROW($W$6))/3) - WEEKDAY(DATE('(필수)설정 시트'!$B$2, $D$1, 1), 1) <= 0, "", IF( (COLUMN()-COLUMN($W$6)+2) + 7*INT((ROW()-ROW($W$6))/3) - WEEKDAY(DATE('(필수)설정 시트'!$B$2, $D$1, 1), 1) > DAY(EOMONTH(DATE('(필수)설정 시트'!$B$2, $D$1, 1), 0)), "", TEXT( DATE('(필수)설정 시트'!$B$2, $D$1, 1) + (COLUMN()-COLUMN($W$6)+2) + 7*INT((ROW()-ROW($W$6))/3) - WEEKDAY(DATE('(필수)설정 시트'!$B$2, $D$1, 1), 1) - 1, "d" ) ) ) | AC6: =IF( (COLUMN()-COLUMN($W$6)+2) + 7*INT((ROW()-ROW($W$6))/3) - WEEKDAY(DATE('(필수)설정 시트'!$B$2, $D$1, 1), 1) <= 0, "", IF( (COLUMN()-COLUMN($W$6)+2) + 7*INT((ROW()-ROW($W$6))/3) - WEEKDAY(DATE('(필수)설정 시트'!$B$2, $D$1, 1), 1) > DAY(EOMONTH(DATE('(필수)설정 시트'!$B$2, $D$1, 1), 0)), "", TEXT( DATE('(필수)설정 시트'!$B$2, $D$1, 1) + (COLUMN()-COLUMN($W$6)+2) + 7*INT((ROW()-ROW($W$6))/3) - WEEKDAY(DATE('(필수)설정 시트'!$B$2, $D$1, 1), 1) - 1, "d" ) ) )
B7: 총 지출 | C7: =SUM($J$6:$J$56) - E34 | M7: =M6-J7 | P7: 🚍교통비 | Q7: =SUMIF($I$6:$I$56,P7,$J$6:$J$56) | T7: 💇미용 | U7: =SUMIF($I$6:$I$56,T7,$J$6:$J$56) | W7: =IFERROR(SUMIF($G$6:$G$56, W6, $J$6:$J$56), "") | X7: =IFERROR(SUMIF($G$6:$G$56, X6, $J$6:$J$56), "") | Y7: =IFERROR(SUMIF($G$6:$G$56, Y6, $J$6:$J$56), "") | Z7: =IFERROR(SUMIF($G$6:$G$56, Z6, $J$6:$J$56), "") | AA7: =IFERROR(SUMIF($G$6:$G$56, AA6, $J$6:$J$56), "") | AB7: =IFERROR(SUMIF($G$6:$G$56, AB6, $J$6:$J$56), "") | AC7: =IFERROR(SUMIF($G$6:$G$56, AC6, $J$6:$J$56), "")
B8: 총 저축 | C8: =E34 | M8: =M7-J8 | P8: 📺스트리밍 서비스 | Q8: =SUMIF($I$6:$I$56,P8,$J$6:$J$56) | T8: 💬잡화 | U8: =SUMIF($I$6:$I$56,T8,$J$6:$J$56)
B9: 총 저축률 | C9: =C8/C6 | M9: =M8-J9 | P9: 🎵멜론 | Q9: =SUMIF($I$6:$I$56,P9,$J$6:$J$56) | U9: =SUMIF($I$6:$I$56,T9,$J$6:$J$56) | W9: =IF( (COLUMN()-COLUMN($W$6)+2) + 7*INT((ROW()-ROW($W$6))/3) - WEEKDAY(DATE('(필수)설정 시트'!$B$2, $D$1, 1), 1) <= 0, "", IF( (COLUMN()-COLUMN($W$6)+2) + 7*INT((ROW()-ROW($W$6))/3) - WEEKDAY(DATE('(필수)설정 시트'!$B$2, $D$1, 1), 1) > DAY(EOMONTH(DATE('(필수)설정 시트'!$B$2, $D$1, 1), 0)), "", TEXT( DATE('(필수)설정 시트'!$B$2, $D$1, 1) + (COLUMN()-COLUMN($W$6)+2) + 7*INT((ROW()-ROW($W$6))/3) - WEEKDAY(DATE('(필수)설정 시트'!$B$2, $D$1, 1), 1) - 1, "d" ) ) ) | X9: =IF( (COLUMN()-COLUMN($W$6)+2) + 7*INT((ROW()-ROW($W$6))/3) - WEEKDAY(DATE('(필수)설정 시트'!$B$2, $D$1, 1), 1) <= 0, "", IF( (COLUMN()-COLUMN($W$6)+2) + 7*INT((ROW()-ROW($W$6))/3) - WEEKDAY(DATE('(필수)설정 시트'!$B$2, $D$1, 1), 1) > DAY(EOMONTH(DATE('(필수)설정 시트'!$B$2, $D$1, 1), 0)), "", TEXT( DATE('(필수)설정 시트'!$B$2, $D$1, 1) + (COLUMN()-COLUMN($W$6)+2) + 7*INT((ROW()-ROW($W$6))/3) - WEEKDAY(DATE('(필수)설정 시트'!$B$2, $D$1, 1), 1) - 1, "d" ) ) ) | Y9: =IF( (COLUMN()-COLUMN($W$6)+2) + 7*INT((ROW()-ROW($W$6))/3) - WEEKDAY(DATE('(필수)설정 시트'!$B$2, $D$1, 1), 1) <= 0, "", IF( (COLUMN()-COLUMN($W$6)+2) + 7*INT((ROW()-ROW($W$6))/3) - WEEKDAY(DATE('(필수)설정 시트'!$B$2, $D$1, 1), 1) > DAY(EOMONTH(DATE('(필수)설정 시트'!$B$2, $D$1, 1), 0)), "", TEXT( DATE('(필수)설정 시트'!$B$2, $D$1, 1) + (COLUMN()-COLUMN($W$6)+2) + 7*INT((ROW()-ROW($W$6))/3) - WEEKDAY(DATE('(필수)설정 시트'!$B$2, $D$1, 1), 1) - 1, "d" ) ) ) | Z9: =IF( (COLUMN()-COLUMN($W$6)+2) + 7*INT((ROW()-ROW($W$6))/3) - WEEKDAY(DATE('(필수)설정 시트'!$B$2, $D$1, 1), 1) <= 0, "", IF( (COLUMN()-COLUMN($W$6)+2) + 7*INT((ROW()-ROW($W$6))/3) - WEEKDAY(DATE('(필수)설정 시트'!$B$2, $D$1, 1), 1) > DAY(EOMONTH(DATE('(필수)설정 시트'!$B$2, $D$1, 1), 0)), "", TEXT( DATE('(필수)설정 시트'!$B$2, $D$1, 1) + (COLUMN()-COLUMN($W$6)+2) + 7*INT((ROW()-ROW($W$6))/3) - WEEKDAY(DATE('(필수)설정 시트'!$B$2, $D$1, 1), 1) - 1, "d" ) ) ) | AA9: =IF( (COLUMN()-COLUMN($W$6)+2) + 7*INT((ROW()-ROW($W$6))/3) - WEEKDAY(DATE('(필수)설정 시트'!$B$2, $D$1, 1), 1) <= 0, "", IF( (COLUMN()-COLUMN($W$6)+2) + 7*INT((ROW()-ROW($W$6))/3) - WEEKDAY(DATE('(필수)설정 시트'!$B$2, $D$1, 1), 1) > DAY(EOMONTH(DATE('(필수)설정 시트'!$B$2, $D$1, 1), 0)), "", TEXT( DATE('(필수)설정 시트'!$B$2, $D$1, 1) + (COLUMN()-COLUMN($W$6)+2) + 7*INT((ROW()-ROW($W$6))/3) - WEEKDAY(DATE('(필수)설정 시트'!$B$2, $D$1, 1), 1) - 1, "d" ) ) ) | AB9: =IF( (COLUMN()-COLUMN($W$6)+2) + 7*INT((ROW()-ROW($W$6))/3) - WEEKDAY(DATE('(필수)설정 시트'!$B$2, $D$1, 1), 1) <= 0, "", IF( (COLUMN()-COLUMN($W$6)+2) + 7*INT((ROW()-ROW($W$6))/3) - WEEKDAY(DATE('(필수)설정 시트'!$B$2, $D$1, 1), 1) > DAY(EOMONTH(DATE('(필수)설정 시트'!$B$2, $D$1, 1), 0)), "", TEXT( DATE('(필수)설정 시트'!$B$2, $D$1, 1) + (COLUMN()-COLUMN($W$6)+2) + 7*INT((ROW()-ROW($W$6))/3) - WEEKDAY(DATE('(필수)설정 시트'!$B$2, $D$1, 1), 1) - 1, "d" ) ) ) | AC9: =IF( (COLUMN()-COLUMN($W$6)+2) + 7*INT((ROW()-ROW($W$6))/3) - WEEKDAY(DATE('(필수)설정 시트'!$B$2, $D$1, 1), 1) <= 0, "", IF( (COLUMN()-COLUMN($W$6)+2) + 7*INT((ROW()-ROW($W$6))/3) - WEEKDAY(DATE('(필수)설정 시트'!$B$2, $D$1, 1), 1) > DAY(EOMONTH(DATE('(필수)설정 시트'!$B$2, $D$1, 1), 0)), "", TEXT( DATE('(필수)설정 시트'!$B$2, $D$1, 1) + (COLUMN()-COLUMN($W$6)+2) + 7*INT((ROW()-ROW($W$6))/3) - WEEKDAY(DATE('(필수)설정 시트'!$B$2, $D$1, 1), 1) - 1, "d" ) ) )
B10: 보유 현금 | M10: =M9-J10 | P10: 🛡️보험료 | Q10: =SUMIF($I$6:$I$56,P10,$J$6:$J$56) | U10: =SUMIF($I$6:$I$56,T10,$J$6:$J$56) | W10: =IFERROR(SUMIF($G$6:$G$56, W9, $J$6:$J$56), "") | X10: =IFERROR(SUMIF($G$6:$G$56, X9, $J$6:$J$56), "") | Y10: =IFERROR(SUMIF($G$6:$G$56, Y9, $J$6:$J$56), "") | Z10: =IFERROR(SUMIF($G$6:$G$56, Z9, $J$6:$J$56), "") | AA10: =IFERROR(SUMIF($G$6:$G$56, AA9, $J$6:$J$56), "") | AB10: =IFERROR(SUMIF($G$6:$G$56, AB9, $J$6:$J$56), "") | AC10: =IFERROR(SUMIF($G$6:$G$56, AC9, $J$6:$J$56), "")
B11: 월급에 대한 저축률 | C11: =C8/E15 | M11: =M10-J11 | P11: 🏠생활비 | Q11: =SUMIF($I$6:$I$56,P11,$J$6:$J$56) | U11: =SUMIF($I$6:$I$56,T11,$J$6:$J$56)
M12: =M11-J12 | P12: 💬카카오이모티콘 | Q12: =SUMIF($I$6:$I$56,P12,$J$6:$J$56) | S12: ='(필수)설정 시트'!E46 | U12: =SUM(U6:U11) | W12: =IF( (COLUMN()-COLUMN($W$6)+2) + 7*INT((ROW()-ROW($W$6))/3) - WEEKDAY(DATE('(필수)설정 시트'!$B$2, $D$1, 1), 1) <= 0, "", IF( (COLUMN()-COLUMN($W$6)+2) + 7*INT((ROW()-ROW($W$6))/3) - WEEKDAY(DATE('(필수)설정 시트'!$B$2, $D$1, 1), 1) > DAY(EOMONTH(DATE('(필수)설정 시트'!$B$2, $D$1, 1), 0)), "", TEXT( DATE('(필수)설정 시트'!$B$2, $D$1, 1) + (COLUMN()-COLUMN($W$6)+2) + 7*INT((ROW()-ROW($W$6))/3) - WEEKDAY(DATE('(필수)설정 시트'!$B$2, $D$1, 1), 1) - 1, "d" ) ) ) | X12: =IF( (COLUMN()-COLUMN($W$6)+2) + 7*INT((ROW()-ROW($W$6))/3) - WEEKDAY(DATE('(필수)설정 시트'!$B$2, $D$1, 1), 1) <= 0, "", IF( (COLUMN()-COLUMN($W$6)+2) + 7*INT((ROW()-ROW($W$6))/3) - WEEKDAY(DATE('(필수)설정 시트'!$B$2, $D$1, 1), 1) > DAY(EOMONTH(DATE('(필수)설정 시트'!$B$2, $D$1, 1), 0)), "", TEXT( DATE('(필수)설정 시트'!$B$2, $D$1, 1) + (COLUMN()-COLUMN($W$6)+2) + 7*INT((ROW()-ROW($W$6))/3) - WEEKDAY(DATE('(필수)설정 시트'!$B$2, $D$1, 1), 1) - 1, "d" ) ) ) | Y12: =IF( (COLUMN()-COLUMN($W$6)+2) + 7*INT((ROW()-ROW($W$6))/3) - WEEKDAY(DATE('(필수)설정 시트'!$B$2, $D$1, 1), 1) <= 0, "", IF( (COLUMN()-COLUMN($W$6)+2) + 7*INT((ROW()-ROW($W$6))/3) - WEEKDAY(DATE('(필수)설정 시트'!$B$2, $D$1, 1), 1) > DAY(EOMONTH(DATE('(필수)설정 시트'!$B$2, $D$1, 1), 0)), "", TEXT( DATE('(필수)설정 시트'!$B$2, $D$1, 1) + (COLUMN()-COLUMN($W$6)+2) + 7*INT((ROW()-ROW($W$6))/3) - WEEKDAY(DATE('(필수)설정 시트'!$B$2, $D$1, 1), 1) - 1, "d" ) ) ) | Z12: =IF( (COLUMN()-COLUMN($W$6)+2) + 7*INT((ROW()-ROW($W$6))/3) - WEEKDAY(DATE('(필수)설정 시트'!$B$2, $D$1, 1), 1) <= 0, "", IF( (COLUMN()-COLUMN($W$6)+2) + 7*INT((ROW()-ROW($W$6))/3) - WEEKDAY(DATE('(필수)설정 시트'!$B$2, $D$1, 1), 1) > DAY(EOMONTH(DATE('(필수)설정 시트'!$B$2, $D$1, 1), 0)), "", TEXT( DATE('(필수)설정 시트'!$B$2, $D$1, 1) + (COLUMN()-COLUMN($W$6)+2) + 7*INT((ROW()-ROW($W$6))/3) - WEEKDAY(DATE('(필수)설정 시트'!$B$2, $D$1, 1), 1) - 1, "d" ) ) ) | AA12: =IF( (COLUMN()-COLUMN($W$6)+2) + 7*INT((ROW()-ROW($W$6))/3) - WEEKDAY(DATE('(필수)설정 시트'!$B$2, $D$1, 1), 1) <= 0, "", IF( (COLUMN()-COLUMN($W$6)+2) + 7*INT((ROW()-ROW($W$6))/3) - WEEKDAY(DATE('(필수)설정 시트'!$B$2, $D$1, 1), 1) > DAY(EOMONTH(DATE('(필수)설정 시트'!$B$2, $D$1, 1), 0)), "", TEXT( DATE('(필수)설정 시트'!$B$2, $D$1, 1) + (COLUMN()-COLUMN($W$6)+2) + 7*INT((ROW()-ROW($W$6))/3) - WEEKDAY(DATE('(필수)설정 시트'!$B$2, $D$1, 1), 1) - 1, "d" ) ) ) | AB12: =IF( (COLUMN()-COLUMN($W$6)+2) + 7*INT((ROW()-ROW($W$6))/3) - WEEKDAY(DATE('(필수)설정 시트'!$B$2, $D$1, 1), 1) <= 0, "", IF( (COLUMN()-COLUMN($W$6)+2) + 7*INT((ROW()-ROW($W$6))/3) - WEEKDAY(DATE('(필수)설정 시트'!$B$2, $D$1, 1), 1) > DAY(EOMONTH(DATE('(필수)설정 시트'!$B$2, $D$1, 1), 0)), "", TEXT( DATE('(필수)설정 시트'!$B$2, $D$1, 1) + (COLUMN()-COLUMN($W$6)+2) + 7*INT((ROW()-ROW($W$6))/3) - WEEKDAY(DATE('(필수)설정 시트'!$B$2, $D$1, 1), 1) - 1, "d" ) ) ) | AC12: =IF( (COLUMN()-COLUMN($W$6)+2) + 7*INT((ROW()-ROW($W$6))/3) - WEEKDAY(DATE('(필수)설정 시트'!$B$2, $D$1, 1), 1) <= 0, "", IF( (COLUMN()-COLUMN($W$6)+2) + 7*INT((ROW()-ROW($W$6))/3) - WEEKDAY(DATE('(필수)설정 시트'!$B$2, $D$1, 1), 1) > DAY(EOMONTH(DATE('(필수)설정 시트'!$B$2, $D$1, 1), 0)), "", TEXT( DATE('(필수)설정 시트'!$B$2, $D$1, 1) + (COLUMN()-COLUMN($W$6)+2) + 7*INT((ROW()-ROW($W$6))/3) - WEEKDAY(DATE('(필수)설정 시트'!$B$2, $D$1, 1), 1) - 1, "d" ) ) )
B13: 수입 | C13: 분류 | D13: 목표금액 | E13: 합계 | M13: =M12-J13 | P13: 🏡주택청약 | Q13: =SUMIF($I$6:$I$56,P13,$J$6:$J$56) | S13: ='(필수)설정 시트'!E47 | T13: 👨‍👩‍👧가족 | U13: =SUMIF($I$6:$I$56,T13,$J$6:$J$56) | W13: =IFERROR(SUMIF($G$6:$G$56, W12, $J$6:$J$56), "") | X13: =IFERROR(SUMIF($G$6:$G$56, X12, $J$6:$J$56), "") | Y13: =IFERROR(SUMIF($G$6:$G$56, Y12, $J$6:$J$56), "") | Z13: =IFERROR(SUMIF($G$6:$G$56, Z12, $J$6:$J$56), "") | AA13: =IFERROR(SUMIF($G$6:$G$56, AA12, $J$6:$J$56), "") | AB13: =IFERROR(SUMIF($G$6:$G$56, AB12, $J$6:$J$56), "") | AC13: =IFERROR(SUMIF($G$6:$G$56, AC12, $J$6:$J$56), "")
M14: =M13-J14 | P14: 💰적금 | Q14: =SUMIF($I$6:$I$56,P14,$J$6:$J$56) | T14: 💑데이트 | U14: =SUMIF($I$6:$I$56,T14,$J$6:$J$56)
C15: ='(필수)설정 시트'!C24 | D15: 0 | E15: 0 | M15: =M13-J15 | T15: 🎁선물 | U15: =SUMIF($I$6:$I$56,T15,$J$6:$J$56)
C16: ='(필수)설정 시트'!C25 | D16: 0 | E16: 0 | M16: =M15-J16 | O16: ='(필수)설정 시트'!E41 | Q16: =SUM($Q$6:$Q$15) | T16: 👥모임 | U16: =SUMIF($I$6:$I$56,T16,$J$6:$J$56) | W16: =IF( (COLUMN()-COLUMN($W$6)+2) + 7*INT((ROW()-ROW($W$6))/3) - WEEKDAY(DATE('(필수)설정 시트'!$B$2, $D$1, 1), 1) <= 0, "", IF( (COLUMN()-COLUMN($W$6)+2) + 7*INT((ROW()-ROW($W$6))/3) - WEEKDAY(DATE('(필수)설정 시트'!$B$2, $D$1, 1), 1) > DAY(EOMONTH(DATE('(필수)설정 시트'!$B$2, $D$1, 1), 0)), "", TEXT( DATE('(필수)설정 시트'!$B$2, $D$1, 1) + (COLUMN()-COLUMN($W$6)+2) + 7*INT((ROW()-ROW($W$6))/3) - WEEKDAY(DATE('(필수)설정 시트'!$B$2, $D$1, 1), 1) - 1, "d" ) ) ) | X16: =IF( (COLUMN()-COLUMN($W$6)+2) + 7*INT((ROW()-ROW($W$6))/3) - WEEKDAY(DATE('(필수)설정 시트'!$B$2, $D$1, 1), 1) <= 0, "", IF( (COLUMN()-COLUMN($W$6)+2) + 7*INT((ROW()-ROW($W$6))/3) - WEEKDAY(DATE('(필수)설정 시트'!$B$2, $D$1, 1), 1) > DAY(EOMONTH(DATE('(필수)설정 시트'!$B$2, $D$1, 1), 0)), "", TEXT( DATE('(필수)설정 시트'!$B$2, $D$1, 1) + (COLUMN()-COLUMN($W$6)+2) + 7*INT((ROW()-ROW($W$6))/3) - WEEKDAY(DATE('(필수)설정 시트'!$B$2, $D$1, 1), 1) - 1, "d" ) ) ) | Y16: =IF( (COLUMN()-COLUMN($W$6)+2) + 7*INT((ROW()-ROW($W$6))/3) - WEEKDAY(DATE('(필수)설정 시트'!$B$2, $D$1, 1), 1) <= 0, "", IF( (COLUMN()-COLUMN($W$6)+2) + 7*INT((ROW()-ROW($W$6))/3) - WEEKDAY(DATE('(필수)설정 시트'!$B$2, $D$1, 1), 1) > DAY(EOMONTH(DATE('(필수)설정 시트'!$B$2, $D$1, 1), 0)), "", TEXT( DATE('(필수)설정 시트'!$B$2, $D$1, 1) + (COLUMN()-COLUMN($W$6)+2) + 7*INT((ROW()-ROW($W$6))/3) - WEEKDAY(DATE('(필수)설정 시트'!$B$2, $D$1, 1), 1) - 1, "d" ) ) ) | Z16: =IF( (COLUMN()-COLUMN($W$6)+2) + 7*INT((ROW()-ROW($W$6))/3) - WEEKDAY(DATE('(필수)설정 시트'!$B$2, $D$1, 1), 1) <= 0, "", IF( (COLUMN()-COLUMN($W$6)+2) + 7*INT((ROW()-ROW($W$6))/3) - WEEKDAY(DATE('(필수)설정 시트'!$B$2, $D$1, 1), 1) > DAY(EOMONTH(DATE('(필수)설정 시트'!$B$2, $D$1, 1), 0)), "", TEXT( DATE('(필수)설정 시트'!$B$2, $D$1, 1) + (COLUMN()-COLUMN($W$6)+2) + 7*INT((ROW()-ROW($W$6))/3) - WEEKDAY(DATE('(필수)설정 시트'!$B$2, $D$1, 1), 1) - 1, "d" ) ) ) | AA16: =IF( (COLUMN()-COLUMN($W$6)+2) + 7*INT((ROW()-ROW($W$6))/3) - WEEKDAY(DATE('(필수)설정 시트'!$B$2, $D$1, 1), 1) <= 0, "", IF( (COLUMN()-COLUMN($W$6)+2) + 7*INT((ROW()-ROW($W$6))/3) - WEEKDAY(DATE('(필수)설정 시트'!$B$2, $D$1, 1), 1) > DAY(EOMONTH(DATE('(필수)설정 시트'!$B$2, $D$1, 1), 0)), "", TEXT( DATE('(필수)설정 시트'!$B$2, $D$1, 1) + (COLUMN()-COLUMN($W$6)+2) + 7*INT((ROW()-ROW($W$6))/3) - WEEKDAY(DATE('(필수)설정 시트'!$B$2, $D$1, 1), 1) - 1, "d" ) ) ) | AB16: =IF( (COLUMN()-COLUMN($W$6)+2) + 7*INT((ROW()-ROW($W$6))/3) - WEEKDAY(DATE('(필수)설정 시트'!$B$2, $D$1, 1), 1) <= 0, "", IF( (COLUMN()-COLUMN($W$6)+2) + 7*INT((ROW()-ROW($W$6))/3) - WEEKDAY(DATE('(필수)설정 시트'!$B$2, $D$1, 1), 1) > DAY(EOMONTH(DATE('(필수)설정 시트'!$B$2, $D$1, 1), 0)), "", TEXT( DATE('(필수)설정 시트'!$B$2, $D$1, 1) + (COLUMN()-COLUMN($W$6)+2) + 7*INT((ROW()-ROW($W$6))/3) - WEEKDAY(DATE('(필수)설정 시트'!$B$2, $D$1, 1), 1) - 1, "d" ) ) ) | AC16: =IF( (COLUMN()-COLUMN($W$6)+2) + 7*INT((ROW()-ROW($W$6))/3) - WEEKDAY(DATE('(필수)설정 시트'!$B$2, $D$1, 1), 1) <= 0, "", IF( (COLUMN()-COLUMN($W$6)+2) + 7*INT((ROW()-ROW($W$6))/3) - WEEKDAY(DATE('(필수)설정 시트'!$B$2, $D$1, 1), 1) > DAY(EOMONTH(DATE('(필수)설정 시트'!$B$2, $D$1, 1), 0)), "", TEXT( DATE('(필수)설정 시트'!$B$2, $D$1, 1) + (COLUMN()-COLUMN($W$6)+2) + 7*INT((ROW()-ROW($W$6))/3) - WEEKDAY(DATE('(필수)설정 시트'!$B$2, $D$1, 1), 1) - 1, "d" ) ) )
C17: ='(필수)설정 시트'!C26 | D17: 0 | E17: 0 | M17: =M16-J17 | O17: ='(필수)설정 시트'!E42 | P17: 🚇지하철비 | Q17: =SUMIF($I$6:$I$56,P17,$J$6:$J$56) | T17: 🧑‍🤝‍🧑지인 | U17: =SUMIF($I$6:$I$56,T17,$J$6:$J$56) | W17: =IFERROR(SUMIF($G$6:$G$56, W16, $J$6:$J$56), "") | X17: =IFERROR(SUMIF($G$6:$G$56, X16, $J$6:$J$56), "") | Y17: =IFERROR(SUMIF($G$6:$G$56, Y16, $J$6:$J$56), "") | Z17: =IFERROR(SUMIF($G$6:$G$56, Z16, $J$6:$J$56), "") | AA17: =IFERROR(SUMIF($G$6:$G$56, AA16, $J$6:$J$56), "") | AB17: =IFERROR(SUMIF($G$6:$G$56, AB16, $J$6:$J$56), "") | AC17: =IFERROR(SUMIF($G$6:$G$56, AC16, $J$6:$J$56), "")
C18: ='(필수)설정 시트'!C27 | D18: 0 | E18: 0 | M18: =M17-J18 | P18: 🚕택시비 | Q18: =SUMIF($I$6:$I$56,P18,$J$6:$J$56) | U18: =SUMIF($I$6:$I$56,T18,$J$6:$J$56)
C19: ='(필수)설정 시트'!C28 | D19: 0 | E19: 0 | M19: =M18-J19 | P19: 🅿️주차비 | Q19: =SUMIF($I$6:$I$56,P19,$J$6:$J$56) | U19: =SUMIF($I$6:$I$56,T19,$J$6:$J$56) | W19: =IF( (COLUMN()-COLUMN($W$6)+2) + 7*INT((ROW()-ROW($W$6))/3) - WEEKDAY(DATE('(필수)설정 시트'!$B$2, $D$1, 1), 1) <= 0, "", IF( (COLUMN()-COLUMN($W$6)+2) + 7*INT((ROW()-ROW($W$6))/3) - WEEKDAY(DATE('(필수)설정 시트'!$B$2, $D$1, 1), 1) > DAY(EOMONTH(DATE('(필수)설정 시트'!$B$2, $D$1, 1), 0)), "", TEXT( DATE('(필수)설정 시트'!$B$2, $D$1, 1) + (COLUMN()-COLUMN($W$6)+2) + 7*INT((ROW()-ROW($W$6))/3) - WEEKDAY(DATE('(필수)설정 시트'!$B$2, $D$1, 1), 1) - 1, "d" ) ) ) | X19: =IF( (COLUMN()-COLUMN($W$6)+2) + 7*INT((ROW()-ROW($W$6))/3) - WEEKDAY(DATE('(필수)설정 시트'!$B$2, $D$1, 1), 1) <= 0, "", IF( (COLUMN()-COLUMN($W$6)+2) + 7*INT((ROW()-ROW($W$6))/3) - WEEKDAY(DATE('(필수)설정 시트'!$B$2, $D$1, 1), 1) > DAY(EOMONTH(DATE('(필수)설정 시트'!$B$2, $D$1, 1), 0)), "", TEXT( DATE('(필수)설정 시트'!$B$2, $D$1, 1) + (COLUMN()-COLUMN($W$6)+2) + 7*INT((ROW()-ROW($W$6))/3) - WEEKDAY(DATE('(필수)설정 시트'!$B$2, $D$1, 1), 1) - 1, "d" ) ) ) | Y19: =IF( (COLUMN()-COLUMN($W$6)+2) + 7*INT((ROW()-ROW($W$6))/3) - WEEKDAY(DATE('(필수)설정 시트'!$B$2, $D$1, 1), 1) <= 0, "", IF( (COLUMN()-COLUMN($W$6)+2) + 7*INT((ROW()-ROW($W$6))/3) - WEEKDAY(DATE('(필수)설정 시트'!$B$2, $D$1, 1), 1) > DAY(EOMONTH(DATE('(필수)설정 시트'!$B$2, $D$1, 1), 0)), "", TEXT( DATE('(필수)설정 시트'!$B$2, $D$1, 1) + (COLUMN()-COLUMN($W$6)+2) + 7*INT((ROW()-ROW($W$6))/3) - WEEKDAY(DATE('(필수)설정 시트'!$B$2, $D$1, 1), 1) - 1, "d" ) ) ) | Z19: =IF( (COLUMN()-COLUMN($W$6)+2) + 7*INT((ROW()-ROW($W$6))/3) - WEEKDAY(DATE('(필수)설정 시트'!$B$2, $D$1, 1), 1) <= 0, "", IF( (COLUMN()-COLUMN($W$6)+2) + 7*INT((ROW()-ROW($W$6))/3) - WEEKDAY(DATE('(필수)설정 시트'!$B$2, $D$1, 1), 1) > DAY(EOMONTH(DATE('(필수)설정 시트'!$B$2, $D$1, 1), 0)), "", TEXT( DATE('(필수)설정 시트'!$B$2, $D$1, 1) + (COLUMN()-COLUMN($W$6)+2) + 7*INT((ROW()-ROW($W$6))/3) - WEEKDAY(DATE('(필수)설정 시트'!$B$2, $D$1, 1), 1) - 1, "d" ) ) ) | AA19: =IF( (COLUMN()-COLUMN($W$6)+2) + 7*INT((ROW()-ROW($W$6))/3) - WEEKDAY(DATE('(필수)설정 시트'!$B$2, $D$1, 1), 1) <= 0, "", IF( (COLUMN()-COLUMN($W$6)+2) + 7*INT((ROW()-ROW($W$6))/3) - WEEKDAY(DATE('(필수)설정 시트'!$B$2, $D$1, 1), 1) > DAY(EOMONTH(DATE('(필수)설정 시트'!$B$2, $D$1, 1), 0)), "", TEXT( DATE('(필수)설정 시트'!$B$2, $D$1, 1) + (COLUMN()-COLUMN($W$6)+2) + 7*INT((ROW()-ROW($W$6))/3) - WEEKDAY(DATE('(필수)설정 시트'!$B$2, $D$1, 1), 1) - 1, "d" ) ) ) | AB19: =IF( (COLUMN()-COLUMN($W$6)+2) + 7*INT((ROW()-ROW($W$6))/3) - WEEKDAY(DATE('(필수)설정 시트'!$B$2, $D$1, 1), 1) <= 0, "", IF( (COLUMN()-COLUMN($W$6)+2) + 7*INT((ROW()-ROW($W$6))/3) - WEEKDAY(DATE('(필수)설정 시트'!$B$2, $D$1, 1), 1) > DAY(EOMONTH(DATE('(필수)설정 시트'!$B$2, $D$1, 1), 0)), "", TEXT( DATE('(필수)설정 시트'!$B$2, $D$1, 1) + (COLUMN()-COLUMN($W$6)+2) + 7*INT((ROW()-ROW($W$6))/3) - WEEKDAY(DATE('(필수)설정 시트'!$B$2, $D$1, 1), 1) - 1, "d" ) ) ) | AC19: =IF( (COLUMN()-COLUMN($W$6)+2) + 7*INT((ROW()-ROW($W$6))/3) - WEEKDAY(DATE('(필수)설정 시트'!$B$2, $D$1, 1), 1) <= 0, "", IF( (COLUMN()-COLUMN($W$6)+2) + 7*INT((ROW()-ROW($W$6))/3) - WEEKDAY(DATE('(필수)설정 시트'!$B$2, $D$1, 1), 1) > DAY(EOMONTH(DATE('(필수)설정 시트'!$B$2, $D$1, 1), 0)), "", TEXT( DATE('(필수)설정 시트'!$B$2, $D$1, 1) + (COLUMN()-COLUMN($W$6)+2) + 7*INT((ROW()-ROW($W$6))/3) - WEEKDAY(DATE('(필수)설정 시트'!$B$2, $D$1, 1), 1) - 1, "d" ) ) )
B20: 총 수입 | E20: =SUM(E15:E19) | M20: =M19-J20 | P20: ⛽주유비 | Q20: =SUMIF($I$6:$I$56,P20,$J$6:$J$56) | S20: ='(필수)설정 시트'!E47 | U20: =SUM(U13:U19) | W20: =IFERROR(SUMIF($G$6:$G$56, W19, $J$6:$J$56), "") | X20: =IFERROR(SUMIF($G$6:$G$56, X19, $J$6:$J$56), "") | Y20: =IFERROR(SUMIF($G$6:$G$56, Y19, $J$6:$J$56), "") | Z20: =IFERROR(SUMIF($G$6:$G$56, Z19, $J$6:$J$56), "") | AA20: =IFERROR(SUMIF($G$6:$G$56, AA19, $J$6:$J$56), "") | AB20: =IFERROR(SUMIF($G$6:$G$56, AB19, $J$6:$J$56), "") | AC20: =IFERROR(SUMIF($G$6:$G$43, AC19, $J$6:$J$43), "")
B21: 저축 | C21: 분류 | D21: 목표금액 | E21: 합계 | F21: 보험료 고정 | M21: =M20-J21 | Q21: =SUMIF($I$6:$I$56,P21,$J$6:$J$56) | S21: ='(필수)설정 시트'!E48 | T21: 🧧명절 | U21: =SUMIF($I$6:$I$56,T21,$J$6:$J$56)
C22: ='(필수)설정 시트'!F5 | D22: 0 | E22: 0 | M22: =M21-J22 | Q22: =SUMIF($I$6:$I$56,P22,$J$6:$J$56) | U22: =SUMIF($I$6:$I$56,T22,$J$6:$J$56)
D23: 0 | E23: 0 | M23: =M22-J23 | O23: ='(필수)설정 시트'!E42 | Q23: =SUM(Q17:Q22) | U23: =SUMIF($I$6:$I$56,T23,$J$6:$J$56)
D24: 0 | E24: 0 | M24: =M23-J24 | O24: ='(필수)설정 시트'!E43 | P24: ☕간식/카페 | Q24: =SUMIF($I$6:$I$56,P24,$J$6:$J$56) | U24: =SUMIF($I$6:$I$56,T24,$J$6:$J$56)
C25: ='(필수)설정 시트'!F8 | D25: 0 | E25: 0 | M25: =M24-J25 | P25: 🍽️외식 | Q25: =SUMIF($I$6:$I$56,P25,$J$6:$J$56) | U25: =SUMIF($I$6:$I$56,T25,$J$6:$J$56)
C26: ='(필수)설정 시트'!F9 | D26: 0 | E26: 0 | M26: =M25-J26 | P26: 🍱식재료비 | Q26: =SUMIF($I$6:$I$56,P26,$J$6:$J$56) | U26: =SUMIF($I$6:$I$56,T26,$J$6:$J$56)
C27: ='(필수)설정 시트'!F10 | D27: 0 | E27: 0 | M27: =M26-J27 | P27: 🌅아침 | Q27: =SUMIF($I$6:$I$56,P27,$J$6:$J$56) | S27: ='(필수)설정 시트'!E48 | U27: =SUM(U21:U26)
C28: ='(필수)설정 시트'!F11 | D28: 0 | E28: 0 | M28: =M27-J28 | P28: 🍛점심 | Q28: =SUMIF($I$6:$I$56,P28,$J$6:$J$56) | S28: ='(필수)설정 시트'!E49 | T28: 🏥병원 | U28: =SUMIF($I$6:$I$56,T28,$J$6:$J$56)
C29: ='(필수)설정 시트'!F12 | D29: 0 | E29: 0 | M29: =M28-J29 | P29: 🌙저녁 | Q29: =SUMIF($I$6:$I$56,P29,$J$6:$J$56) | T29: 💊약국 | U29: =SUMIF($I$6:$I$56,T29,$J$6:$J$56)
C30: ='(필수)설정 시트'!F13 | D30: 0 | E30: 0 | M30: =M29-J30 | P30: 🛵배달 | Q30: =SUMIF($I$6:$I$56,P30,$J$6:$J$56) | T30: 💊영양제 | U30: =SUMIF($I$6:$I$56,T30,$J$6:$J$56)
C31: ='(필수)설정 시트'!F14 | D31: 0 | E31: 0 | M31: =M30-J31 | O31: ='(필수)설정 시트'!E43 | Q31: =SUM(Q24:Q30) | U31: =SUMIF($I$6:$I$56,T31,$J$6:$J$56)
C32: ='(필수)설정 시트'!F15 | D32: 0 | E32: 0 | M32: =M31-J32 | O32: ='(필수)설정 시트'!E44 | P32: 🎓강의 | Q32: =SUMIF($I$6:$I$56,P32,$J$6:$J$56) | U32: =SUMIF($I$6:$I$56,T32,$J$6:$J$56)
C33: ='(필수)설정 시트'!F16 | D33: 0 | E33: 0 | M33: =M32-J33 | P33: 🪪자격증 | Q33: =SUMIF($I$6:$I$56,P33,$J$6:$J$56) | U33: =SUMIF($I$6:$I$56,T33,$J$6:$J$56)
B34: 총 저축 | E34: =SUM(E22:E33) | M34: =M33-J34 | P34: 📚도서 | Q34: =SUMIF($I$6:$I$56,P34,$J$6:$J$56) | S34: ='(필수)설정 시트'!E49 | U34: =SUM(U28:U33)
M35: =M34-J35 | P35: 🤖AI | Q35: =SUMIF($I$6:$I$56,P35,$J$6:$J$56) | S35: ='(필수)설정 시트'!E50 | T35: 💸축의금 | U35: =SUMIF($I$6:$I$56,T35,$J$6:$J$56)
M36: =M35-J36 | Q36: =SUMIF($I$6:$I$56,P36,$J$6:$J$56) | T36: 🖤부의금 | U36: =SUMIF($I$6:$I$56,T36,$J$6:$J$56)
M37: =M36-J37 | Q37: =SUMIF($I$6:$I$56,P37,$J$6:$J$56) | U37: =SUMIF($I$6:$I$56,T37,$J$6:$J$56)
M38: =M37-J38 | O38: ='(필수)설정 시트'!E44 | Q38: =SUM(Q32:Q37) | U38: =SUMIF($I$6:$I$56,T38,$J$6:$J$56)
M39: =M38-J39 | O39: ='(필수)설정 시트'!E45 | P39: 🎭문화생활 | Q39: =SUMIF($I$6:$I$56,P39,$J$6:$J$56) | U39: =SUMIF($I$6:$I$56,T39,$J$6:$J$56)
M40: =M39-J40 | P40: ✈️여행 | Q40: =SUMIF($I$6:$I$56,P40,$J$6:$J$56) | U40: =SUMIF($I$6:$I$56,T40,$J$6:$J$56)
...

Sheet 2월
D1: 1
B2: ='(필수)설정 시트'!B2 | F2: 총 수입 | H2: 총 저축 | J2: 총 지출 비용 | L2: 남은 잔액(부수입 제외)
F3: =C6 | H3: =C8 | J3: =C7 | L3: =(C6-E18)-C7-C8
H4: 항목 변경 시 데이터 확인 규칙 변경 필요
B5: 분류 | C5: 금액 | D5: 결제수단 | E5: 금액 | G5: 날짜[숫자만 입력] | H5: 대분류 | I5: 소분류 | J5: 금액 | K5: 결제수단 | L5: 세부사항 | M5: 남은 잔액 | O5: 대분류 | P5: 소분류 | Q5: 지출금액 | S5: 대분류 | T5: 소분류 | U5: 지출금액 | W5: 일 | X5: 월 | Y5: 화 | Z5: 수 | AA5: 목 | AB5: 금 | AC5: 토
B6: 총 수입 | C6: =E20 | M6: =$E$20-J6 | O6: ='(필수)설정 시트'!E41 | P6: 📱통신비 | Q6: =SUMIF($I$6:$I$56,P6,$J$6:$J$56) | S6: ='(필수)설정 시트'!E46 | T6: 👕의류 | U6: =SUMIF($I$6:$I$56,T6,$J$6:$J$56) | W6: =IF( (COLUMN()-COLUMN($W$6)+2) + 7*INT((ROW()-ROW($W$6))/3) - WEEKDAY(DATE('(필수)설정 시트'!$B$2, $D$1, 1), 1) <= 0, "", IF( (COLUMN()-COLUMN($W$6)+2) + 7*INT((ROW()-ROW($W$6))/3) - WEEKDAY(DATE('(필수)설정 시트'!$B$2, $D$1, 1), 1) > DAY(EOMONTH(DATE('(필수)설정 시트'!$B$2, $D$1, 1), 0)), "", TEXT( DATE('(필수)설정 시트'!$B$2, $D$1, 1) + (COLUMN()-COLUMN($W$6)+2) + 7*INT((ROW()-ROW($W$6))/3) - WEEKDAY(DATE('(필수)설정 시트'!$B$2, $D$1, 1), 1) - 1, "d" ) ) ) | X6: =IF( (COLUMN()-COLUMN($W$6)+2) + 7*INT((ROW()-ROW($W$6))/3) - WEEKDAY(DATE('(필수)설정 시트'!$B$2, $D$1, 1), 1) <= 0, "", IF( (COLUMN()-COLUMN($W$6)+2) + 7*INT((ROW()-ROW($W$6))/3) - WEEKDAY(DATE('(필수)설정 시트'!$B$2, $D$1, 1), 1) > DAY(EOMONTH(DATE('(필수)설정 시트'!$B$2, $D$1, 1), 0)), "", TEXT( DATE('(필수)설정 시트'!$B$2, $D$1, 1) + (COLUMN()-COLUMN($W$6)+2) + 7*INT((ROW()-ROW($W$6))/3) - WEEKDAY(DATE('(필수)설정 시트'!$B$2, $D$1, 1), 1) - 1, "d" ) ) ) | Y6: =IF( (COLUMN()-COLUMN($W$6)+2) + 7*INT((ROW()-ROW($W$6))/3) - WEEKDAY(DATE('(필수)설정 시트'!$B$2, $D$1, 1), 1) <= 0, "", IF( (COLUMN()-COLUMN($W$6)+2) + 7*INT((ROW()-ROW($W$6))/3) - WEEKDAY(DATE('(필수)설정 시트'!$B$2, $D$1, 1), 1) > DAY(EOMONTH(DATE('(필수)설정 시트'!$B$2, $D$1, 1), 0)), "", TEXT( DATE('(필수)설정 시트'!$B$2, $D$1, 1) + (COLUMN()-COLUMN($W$6)+2) + 7*INT((ROW()-ROW($W$6))/3) - WEEKDAY(DATE('(필수)설정 시트'!$B$2, $D$1, 1), 1) - 1, "d" ) ) ) | Z6: =IF( (COLUMN()-COLUMN($W$6)+2) + 7*INT((ROW()-ROW($W$6))/3) - WEEKDAY(DATE('(필수)설정 시트'!$B$2, $D$1, 1), 1) <= 0, "", IF( (COLUMN()-COLUMN($W$6)+2) + 7*INT((ROW()-ROW($W$6))/3) - WEEKDAY(DATE('(필수)설정 시트'!$B$2, $D$1, 1), 1) > DAY(EOMONTH(DATE('(필수)설정 시트'!$B$2, $D$1, 1), 0)), "", TEXT( DATE('(필수)설정 시트'!$B$2, $D$1, 1) + (COLUMN()-COLUMN($W$6)+2) + 7*INT((ROW()-ROW($W$6))/3) - WEEKDAY(DATE('(필수)설정 시트'!$B$2, $D$1, 1), 1) - 1, "d" ) ) ) | AA6: =IF( (COLUMN()-COLUMN($W$6)+2) + 7*INT((ROW()-ROW($W$6))/3) - WEEKDAY(DATE('(필수)설정 시트'!$B$2, $D$1, 1), 1) <= 0, "", IF( (COLUMN()-COLUMN($W$6)+2) + 7*INT((ROW()-ROW($W$6))/3) - WEEKDAY(DATE('(필수)설정 시트'!$B$2, $D$1, 1), 1) > DAY(EOMONTH(DATE('(필수)설정 시트'!$B$2, $D$1, 1), 0)), "", TEXT( DATE('(필수)설정 시트'!$B$2, $D$1, 1) + (COLUMN()-COLUMN($W$6)+2) + 7*INT((ROW()-ROW($W$6))/3) - WEEKDAY(DATE('(필수)설정 시트'!$B$2, $D$1, 1), 1) - 1, "d" ) ) ) | AB6: =IF( (COLUMN()-COLUMN($W$6)+2) + 7*INT((ROW()-ROW($W$6))/3) - WEEKDAY(DATE('(필수)설정 시트'!$B$2, $D$1, 1), 1) <= 0, "", IF( (COLUMN()-COLUMN($W$6)+2) + 7*INT((ROW()-ROW($W$6))/3) - WEEKDAY(DATE('(필수)설정 시트'!$B$2, $D$1, 1), 1) > DAY(EOMONTH(DATE('(필수)설정 시트'!$B$2, $D$1, 1), 0)), "", TEXT( DATE('(필수)설정 시트'!$B$2, $D$1, 1) + (COLUMN()-COLUMN($W$6)+2) + 7*INT((ROW()-ROW($W$6))/3) - WEEKDAY(DATE('(필수)설정 시트'!$B$2, $D$1, 1), 1) - 1, "d" ) ) ) | AC6: =IF( (COLUMN()-COLUMN($W$6)+2) + 7*INT((ROW()-ROW($W$6))/3) - WEEKDAY(DATE('(필수)설정 시트'!$B$2, $D$1, 1), 1) <= 0, "", IF( (COLUMN()-COLUMN($W$6)+2) + 7*INT((ROW()-ROW($W$6))/3) - WEEKDAY(DATE('(필수)설정 시트'!$B$2, $D$1, 1), 1) > DAY(EOMONTH(DATE('(필수)설정 시트'!$B$2, $D$1, 1), 0)), "", TEXT( DATE('(필수)설정 시트'!$B$2, $D$1, 1) + (COLUMN()-COLUMN($W$6)+2) + 7*INT((ROW()-ROW($W$6))/3) - WEEKDAY(DATE('(필수)설정 시트'!$B$2, $D$1, 1), 1) - 1, "d" ) ) )
B7: 총 지출 | C7: =SUM($J$6:$J$56) - E34 | M7: =M6-J7 | P7: 🚍교통비 | Q7: =SUMIF($I$6:$I$56,P7,$J$6:$J$56) | T7: 💇미용 | U7: =SUMIF($I$6:$I$56,T7,$J$6:$J$56) | W7: =IFERROR(SUMIF($G$6:$G$56, W6, $J$6:$J$56), "") | X7: =IFERROR(SUMIF($G$6:$G$56, X6, $J$6:$J$56), "") | Y7: =IFERROR(SUMIF($G$6:$G$56, Y6, $J$6:$J$56), "") | Z7: =IFERROR(SUMIF($G$6:$G$56, Z6, $J$6:$J$56), "") | AA7: =IFERROR(SUMIF($G$6:$G$56, AA6, $J$6:$J$56), "") | AB7: =IFERROR(SUMIF($G$6:$G$56, AB6, $J$6:$J$56), "") | AC7: =IFERROR(SUMIF($G$6:$G$56, AC6, $J$6:$J$56), "")
B8: 총 저축 | C8: =E34 | M8: =M7-J8 | P8: 📺스트리밍 서비스 | Q8: =SUMIF($I$6:$I$56,P8,$J$6:$J$56) | T8: 💬잡화 | U8: =SUMIF($I$6:$I$56,T8,$J$6:$J$56)
B9: 총 저축률 | C9: =C8/C6 | M9: =M8-J9 | P9: 🎵멜론 | Q9: =SUMIF($I$6:$I$56,P9,$J$6:$J$56) | U9: =SUMIF($I$6:$I$56,T9,$J$6:$J$56) | W9: =IF( (COLUMN()-COLUMN($W$6)+2) + 7*INT((ROW()-ROW($W$6))/3) - WEEKDAY(DATE('(필수)설정 시트'!$B$2, $D$1, 1), 1) <= 0, "", IF( (COLUMN()-COLUMN($W$6)+2) + 7*INT((ROW()-ROW($W$6))/3) - WEEKDAY(DATE('(필수)설정 시트'!$B$2, $D$1, 1), 1) > DAY(EOMONTH(DATE('(필수)설정 시트'!$B$2, $D$1, 1), 0)), "", TEXT( DATE('(필수)설정 시트'!$B$2, $D$1, 1) + (COLUMN()-COLUMN($W$6)+2) + 7*INT((ROW()-ROW($W$6))/3) - WEEKDAY(DATE('(필수)설정 시트'!$B$2, $D$1, 1), 1) - 1, "d" ) ) ) | X9: =IF( (COLUMN()-COLUMN($W$6)+2) + 7*INT((ROW()-ROW($W$6))/3) - WEEKDAY(DATE('(필수)설정 시트'!$B$2, $D$1, 1), 1) <= 0, "", IF( (COLUMN()-COLUMN($W$6)+2) + 7*INT((ROW()-ROW($W$6))/3) - WEEKDAY(DATE('(필수)설정 시트'!$B$2, $D$1, 1), 1) > DAY(EOMONTH(DATE('(필수)설정 시트'!$B$2, $D$1, 1), 0)), "", TEXT( DATE('(필수)설정 시트'!$B$2, $D$1, 1) + (COLUMN()-COLUMN($W$6)+2) + 7*INT((ROW()-ROW($W$6))/3) - WEEKDAY(DATE('(필수)설정 시트'!$B$2, $D$1, 1), 1) - 1, "d" ) ) ) | Y9: =IF( (COLUMN()-COLUMN($W$6)+2) + 7*INT((ROW()-ROW($W$6))/3) - WEEKDAY(DATE('(필수)설정 시트'!$B$2, $D$1, 1), 1) <= 0, "", IF( (COLUMN()-COLUMN($W$6)+2) + 7*INT((ROW()-ROW($W$6))/3) - WEEKDAY(DATE('(필수)설정 시트'!$B$2, $D$1, 1), 1) > DAY(EOMONTH(DATE('(필수)설정 시트'!$B$2, $D$1, 1), 0)), "", TEXT( DATE('(필수)설정 시트'!$B$2, $D$1, 1) + (COLUMN()-COLUMN($W$6)+2) + 7*INT((ROW()-ROW($W$6))/3) - WEEKDAY(DATE('(필수)설정 시트'!$B$2, $D$1, 1), 1) - 1, "d" ) ) ) | Z9: =IF( (COLUMN()-COLUMN($W$6)+2) + 7*INT((ROW()-ROW($W$6))/3) - WEEKDAY(DATE('(필수)설정 시트'!$B$2, $D$1, 1), 1) <= 0, "", IF( (COLUMN()-COLUMN($W$6)+2) + 7*INT((ROW()-ROW($W$6))/3) - WEEKDAY(DATE('(필수)설정 시트'!$B$2, $D$1, 1), 1) > DAY(EOMONTH(DATE('(필수)설정 시트'!$B$2, $D$1, 1), 0)), "", TEXT( DATE('(필수)설정 시트'!$B$2, $D$1, 1) + (COLUMN()-COLUMN($W$6)+2) + 7*INT((ROW()-ROW($W$6))/3) - WEEKDAY(DATE('(필수)설정 시트'!$B$2, $D$1, 1), 1) - 1, "d" ) ) ) | AA9: =IF( (COLUMN()-COLUMN($W$6)+2) + 7*INT((ROW()-ROW($W$6))/3) - WEEKDAY(DATE('(필수)설정 시트'!$B$2, $D$1, 1), 1) <= 0, "", IF( (COLUMN()-COLUMN($W$6)+2) + 7*INT((ROW()-ROW($W$6))/3) - WEEKDAY(DATE('(필수)설정 시트'!$B$2, $D$1, 1), 1) > DAY(EOMONTH(DATE('(필수)설정 시트'!$B$2, $D$1, 1), 0)), "", TEXT( DATE('(필수)설정 시트'!$B$2, $D$1, 1) + (COLUMN()-COLUMN($W$6)+2) + 7*INT((ROW()-ROW($W$6))/3) - WEEKDAY(DATE('(필수)설정 시트'!$B$2, $D$1, 1), 1) - 1, "d" ) ) ) | AB9: =IF( (COLUMN()-COLUMN($W$6)+2) + 7*INT((ROW()-ROW($W$6))/3) - WEEKDAY(DATE('(필수)설정 시트'!$B$2, $D$1, 1), 1) <= 0, "", IF( (COLUMN()-COLUMN($W$6)+2) + 7*INT((ROW()-ROW($W$6))/3) - WEEKDAY(DATE('(필수)설정 시트'!$B$2, $D$1, 1), 1) > DAY(EOMONTH(DATE('(필수)설정 시트'!$B$2, $D$1, 1), 0)), "", TEXT( DATE('(필수)설정 시트'!$B$2, $D$1, 1) + (COLUMN()-COLUMN($W$6)+2) + 7*INT((ROW()-ROW($W$6))/3) - WEEKDAY(DATE('(필수)설정 시트'!$B$2, $D$1, 1), 1) - 1, "d" ) ) ) | AC9: =IF( (COLUMN()-COLUMN($W$6)+2) + 7*INT((ROW()-ROW($W$6))/3) - WEEKDAY(DATE('(필수)설정 시트'!$B$2, $D$1, 1), 1) <= 0, "", IF( (COLUMN()-COLUMN($W$6)+2) + 7*INT((ROW()-ROW($W$6))/3) - WEEKDAY(DATE('(필수)설정 시트'!$B$2, $D$1, 1), 1) > DAY(EOMONTH(DATE('(필수)설정 시트'!$B$2, $D$1, 1), 0)), "", TEXT( DATE('(필수)설정 시트'!$B$2, $D$1, 1) + (COLUMN()-COLUMN($W$6)+2) + 7*INT((ROW()-ROW($W$6))/3) - WEEKDAY(DATE('(필수)설정 시트'!$B$2, $D$1, 1), 1) - 1, "d" ) ) )
B10: 보유 현금 | M10: =M9-J10 | P10: 🛡️보험료 | Q10: =SUMIF($I$6:$I$56,P10,$J$6:$J$56) | U10: =SUMIF($I$6:$I$56,T10,$J$6:$J$56) | W10: =IFERROR(SUMIF($G$6:$G$56, W9, $J$6:$J$56), "") | X10: =IFERROR(SUMIF($G$6:$G$56, X9, $J$6:$J$56), "") | Y10: =IFERROR(SUMIF($G$6:$G$56, Y9, $J$6:$J$56), "") | Z10: =IFERROR(SUMIF($G$6:$G$56, Z9, $J$6:$J$56), "") | AA10: =IFERROR(SUMIF($G$6:$G$56, AA9, $J$6:$J$56), "") | AB10: =IFERROR(SUMIF($G$6:$G$56, AB9, $J$6:$J$56), "") | AC10: =IFERROR(SUMIF($G$6:$G$56, AC9, $J$6:$J$56), "")
B11: 월급에 대한 저축률 | C11: =C8/E15 | M11: =M10-J11 | P11: 🏠생활비 | Q11: =SUMIF($I$6:$I$56,P11,$J$6:$J$56) | U11: =SUMIF($I$6:$I$56,T11,$J$6:$J$56)
M12: =M11-J12 | P12: 💬카카오이모티콘 | Q12: =SUMIF($I$6:$I$56,P12,$J$6:$J$56) | S12: ='(필수)설정 시트'!E46 | U12: =SUM(U6:U11) | W12: =IF( (COLUMN()-COLUMN($W$6)+2) + 7*INT((ROW()-ROW($W$6))/3) - WEEKDAY(DATE('(필수)설정 시트'!$B$2, $D$1, 1), 1) <= 0, "", IF( (COLUMN()-COLUMN($W$6)+2) + 7*INT((ROW()-ROW($W$6))/3) - WEEKDAY(DATE('(필수)설정 시트'!$B$2, $D$1, 1), 1) > DAY(EOMONTH(DATE('(필수)설정 시트'!$B$2, $D$1, 1), 0)), "", TEXT( DATE('(필수)설정 시트'!$B$2, $D$1, 1) + (COLUMN()-COLUMN($W$6)+2) + 7*INT((ROW()-ROW($W$6))/3) - WEEKDAY(DATE('(필수)설정 시트'!$B$2, $D$1, 1), 1) - 1, "d" ) ) ) | X12: =IF( (COLUMN()-COLUMN($W$6)+2) + 7*INT((ROW()-ROW($W$6))/3) - WEEKDAY(DATE('(필수)설정 시트'!$B$2, $D$1, 1), 1) <= 0, "", IF( (COLUMN()-COLUMN($W$6)+2) + 7*INT((ROW()-ROW($W$6))/3) - WEEKDAY(DATE('(필수)설정 시트'!$B$2, $D$1, 1), 1) > DAY(EOMONTH(DATE('(필수)설정 시트'!$B$2, $D$1, 1), 0)), "", TEXT( DATE('(필수)설정 시트'!$B$2, $D$1, 1) + (COLUMN()-COLUMN($W$6)+2) + 7*INT((ROW()-ROW($W$6))/3) - WEEKDAY(DATE('(필수)설정 시트'!$B$2, $D$1, 1), 1) - 1, "d" ) ) ) | Y12: =IF( (COLUMN()-COLUMN($W$6)+2) + 7*INT((ROW()-ROW($W$6))/3) - WEEKDAY(DATE('(필수)설정 시트'!$B$2, $D$1, 1), 1) <= 0, "", IF( (COLUMN()-COLUMN($W$6)+2) + 7*INT((ROW()-ROW($W$6))/3) - WEEKDAY(DATE('(필수)설정 시트'!$B$2, $D$1, 1), 1) > DAY(EOMONTH(DATE('(필수)설정 시트'!$B$2, $D$1, 1), 0)), "", TEXT( DATE('(필수)설정 시트'!$B$2, $D$1, 1) + (COLUMN()-COLUMN($W$6)+2) + 7*INT((ROW()-ROW($W$6))/3) - WEEKDAY(DATE('(필수)설정 시트'!$B$2, $D$1, 1), 1) - 1, "d" ) ) ) | Z12: =IF( (COLUMN()-COLUMN($W$6)+2) + 7*INT((ROW()-ROW($W$6))/3) - WEEKDAY(DATE('(필수)설정 시트'!$B$2, $D$1, 1), 1) <= 0, "", IF( (COLUMN()-COLUMN($W$6)+2) + 7*INT((ROW()-ROW($W$6))/3) - WEEKDAY(DATE('(필수)설정 시트'!$B$2, $D$1, 1), 1) > DAY(EOMONTH(DATE('(필수)설정 시트'!$B$2, $D$1, 1), 0)), "", TEXT( DATE('(필수)설정 시트'!$B$2, $D$1, 1) + (COLUMN()-COLUMN($W$6)+2) + 7*INT((ROW()-ROW($W$6))/3) - WEEKDAY(DATE('(필수)설정 시트'!$B$2, $D$1, 1), 1) - 1, "d" ) ) ) | AA12: =IF( (COLUMN()-COLUMN($W$6)+2) + 7*INT((ROW()-ROW($W$6))/3) - WEEKDAY(DATE('(필수)설정 시트'!$B$2, $D$1, 1), 1) <= 0, "", IF( (COLUMN()-COLUMN($W$6)+2) + 7*INT((ROW()-ROW($W$6))/3) - WEEKDAY(DATE('(필수)설정 시트'!$B$2, $D$1, 1), 1) > DAY(EOMONTH(DATE('(필수)설정 시트'!$B$2, $D$1, 1), 0)), "", TEXT( DATE('(필수)설정 시트'!$B$2, $D$1, 1) + (COLUMN()-COLUMN($W$6)+2) + 7*INT((ROW()-ROW($W$6))/3) - WEEKDAY(DATE('(필수)설정 시트'!$B$2, $D$1, 1), 1) - 1, "d" ) ) ) | AB12: =IF( (COLUMN()-COLUMN($W$6)+2) + 7*INT((ROW()-ROW($W$6))/3) - WEEKDAY(DATE('(필수)설정 시트'!$B$2, $D$1, 1), 1) <= 0, "", IF( (COLUMN()-COLUMN($W$6)+2) + 7*INT((ROW()-ROW($W$6))/3) - WEEKDAY(DATE('(필수)설정 시트'!$B$2, $D$1, 1), 1) > DAY(EOMONTH(DATE('(필수)설정 시트'!$B$2, $D$1, 1), 0)), "", TEXT( DATE('(필수)설정 시트'!$B$2, $D$1, 1) + (COLUMN()-COLUMN($W$6)+2) + 7*INT((ROW()-ROW($W$6))/3) - WEEKDAY(DATE('(필수)설정 시트'!$B$2, $D$1, 1), 1) - 1, "d" ) ) ) | AC12: =IF( (COLUMN()-COLUMN($W$6)+2) + 7*INT((ROW()-ROW($W$6))/3) - WEEKDAY(DATE('(필수)설정 시트'!$B$2, $D$1, 1), 1) <= 0, "", IF( (COLUMN()-COLUMN($W$6)+2) + 7*INT((ROW()-ROW($W$6))/3) - WEEKDAY(DATE('(필수)설정 시트'!$B$2, $D$1, 1), 1) > DAY(EOMONTH(DATE('(필수)설정 시트'!$B$2, $D$1, 1), 0)), "", TEXT( DATE('(필수)설정 시트'!$B$2, $D$1, 1) + (COLUMN()-COLUMN($W$6)+2) + 7*INT((ROW()-ROW($W$6))/3) - WEEKDAY(DATE('(필수)설정 시트'!$B$2, $D$1, 1), 1) - 1, "d" ) ) )
B13: 수입 | C13: 분류 | D13: 목표금액 | E13: 합계 | M13: =M12-J13 | P13: 🏡주택청약 | Q13: =SUMIF($I$6:$I$56,P13,$J$6:$J$56) | S13: ='(필수)설정 시트'!E47 | T13: 👨‍👩‍👧가족 | U13: =SUMIF($I$6:$I$56,T13,$J$6:$J$56) | W13: =IFERROR(SUMIF($G$6:$G$56, W12, $J$6:$J$56), "") | X13: =IFERROR(SUMIF($G$6:$G$56, X12, $J$6:$J$56), "") | Y13: =IFERROR(SUMIF($G$6:$G$56, Y12, $J$6:$J$56), "") | Z13: =IFERROR(SUMIF($G$6:$G$56, Z12, $J$6:$J$56), "") | AA13: =IFERROR(SUMIF($G$6:$G$56, AA12, $J$6:$J$56), "") | AB13: =IFERROR(SUMIF($G$6:$G$56, AB12, $J$6:$J$56), "") | AC13: =IFERROR(SUMIF($G$6:$G$56, AC12, $J$6:$J$56), "")
M14: =M13-J14 | P14: 💰적금 | Q14: =SUMIF($I$6:$I$56,P14,$J$6:$J$56) | T14: 💑데이트 | U14: =SUMIF($I$6:$I$56,T14,$J$6:$J$56)
C15: ='(필수)설정 시트'!C24 | D15: 0 | E15: 0 | M15: =M13-J15 | T15: 🎁선물 | U15: =SUMIF($I$6:$I$56,T15,$J$6:$J$56)
C16: ='(필수)설정 시트'!C25 | D16: 0 | E16: 0 | M16: =M15-J16 | O16: ='(필수)설정 시트'!E41 | Q16: =SUM($Q$6:$Q$15) | T16: 👥모임 | U16: =SUMIF($I$6:$I$56,T16,$J$6:$J$56) | W16: =IF( (COLUMN()-COLUMN($W$6)+2) + 7*INT((ROW()-ROW($W$6))/3) - WEEKDAY(DATE('(필수)설정 시트'!$B$2, $D$1, 1), 1) <= 0, "", IF( (COLUMN()-COLUMN($W$6)+2) + 7*INT((ROW()-ROW($W$6))/3) - WEEKDAY(DATE('(필수)설정 시트'!$B$2, $D$1, 1), 1) > DAY(EOMONTH(DATE('(필수)설정 시트'!$B$2, $D$1, 1), 0)), "", TEXT( DATE('(필수)설정 시트'!$B$2, $D$1, 1) + (COLUMN()-COLUMN($W$6)+2) + 7*INT((ROW()-ROW($W$6))/3) - WEEKDAY(DATE('(필수)설정 시트'!$B$2, $D$1, 1), 1) - 1, "d" ) ) ) | X16: =IF( (COLUMN()-COLUMN($W$6)+2) + 7*INT((ROW()-ROW($W$6))/3) - WEEKDAY(DATE('(필수)설정 시트'!$B$2, $D$1, 1), 1) <= 0, "", IF( (COLUMN()-COLUMN($W$6)+2) + 7*INT((ROW()-ROW($W$6))/3) - WEEKDAY(DATE('(필수)설정 시트'!$B$2, $D$1, 1), 1) > DAY(EOMONTH(DATE('(필수)설정 시트'!$B$2, $D$1, 1), 0)), "", TEXT( DATE('(필수)설정 시트'!$B$2, $D$1, 1) + (COLUMN()-COLUMN($W$6)+2) + 7*INT((ROW()-ROW($W$6))/3) - WEEKDAY(DATE('(필수)설정 시트'!$B$2, $D$1, 1), 1) - 1, "d" ) ) ) | Y16: =IF( (COLUMN()-COLUMN($W$6)+2) + 7*INT((ROW()-ROW($W$6))/3) - WEEKDAY(DATE('(필수)설정 시트'!$B$2, $D$1, 1), 1) <= 0, "", IF( (COLUMN()-COLUMN($W$6)+2) + 7*INT((ROW()-ROW($W$6))/3) - WEEKDAY(DATE('(필수)설정 시트'!$B$2, $D$1, 1), 1) > DAY(EOMONTH(DATE('(필수)설정 시트'!$B$2, $D$1, 1), 0)), "", TEXT( DATE('(필수)설정 시트'!$B$2, $D$1, 1) + (COLUMN()-COLUMN($W$6)+2) + 7*INT((ROW()-ROW($W$6))/3) - WEEKDAY(DATE('(필수)설정 시트'!$B$2, $D$1, 1), 1) - 1, "d" ) ) ) | Z16: =IF( (COLUMN()-COLUMN($W$6)+2) + 7*INT((ROW()-ROW($W$6))/3) - WEEKDAY(DATE('(필수)설정 시트'!$B$2, $D$1, 1), 1) <= 0, "", IF( (COLUMN()-COLUMN($W$6)+2) + 7*INT((ROW()-ROW($W$6))/3) - WEEKDAY(DATE('(필수)설정 시트'!$B$2, $D$1, 1), 1) > DAY(EOMONTH(DATE('(필수)설정 시트'!$B$2, $D$1, 1), 0)), "", TEXT( DATE('(필수)설정 시트'!$B$2, $D$1, 1) + (COLUMN()-COLUMN($W$6)+2) + 7*INT((ROW()-ROW($W$6))/3) - WEEKDAY(DATE('(필수)설정 시트'!$B$2, $D$1, 1), 1) - 1, "d" ) ) ) | AA16: =IF( (COLUMN()-COLUMN($W$6)+2) + 7*INT((ROW()-ROW($W$6))/3) - WEEKDAY(DATE('(필수)설정 시트'!$B$2, $D$1, 1), 1) <= 0, "", IF( (COLUMN()-COLUMN($W$6)+2) + 7*INT((ROW()-ROW($W$6))/3) - WEEKDAY(DATE('(필수)설정 시트'!$B$2, $D$1, 1), 1) > DAY(EOMONTH(DATE('(필수)설정 시트'!$B$2, $D$1, 1), 0)), "", TEXT( DATE('(필수)설정 시트'!$B$2, $D$1, 1) + (COLUMN()-COLUMN($W$6)+2) + 7*INT((ROW()-ROW($W$6))/3) - WEEKDAY(DATE('(필수)설정 시트'!$B$2, $D$1, 1), 1) - 1, "d" ) ) ) | AB16: =IF( (COLUMN()-COLUMN($W$6)+2) + 7*INT((ROW()-ROW($W$6))/3) - WEEKDAY(DATE('(필수)설정 시트'!$B$2, $D$1, 1), 1) <= 0, "", IF( (COLUMN()-COLUMN($W$6)+2) + 7*INT((ROW()-ROW($W$6))/3) - WEEKDAY(DATE('(필수)설정 시트'!$B$2, $D$1, 1), 1) > DAY(EOMONTH(DATE('(필수)설정 시트'!$B$2, $D$1, 1), 0)), "", TEXT( DATE('(필수)설정 시트'!$B$2, $D$1, 1) + (COLUMN()-COLUMN($W$6)+2) + 7*INT((ROW()-ROW($W$6))/3) - WEEKDAY(DATE('(필수)설정 시트'!$B$2, $D$1, 1), 1) - 1, "d" ) ) ) | AC16: =IF( (COLUMN()-COLUMN($W$6)+2) + 7*INT((ROW()-ROW($W$6))/3) - WEEKDAY(DATE('(필수)설정 시트'!$B$2, $D$1, 1), 1) <= 0, "", IF( (COLUMN()-COLUMN($W$6)+2) + 7*INT((ROW()-ROW($W$6))/3) - WEEKDAY(DATE('(필수)설정 시트'!$B$2, $D$1, 1), 1) > DAY(EOMONTH(DATE('(필수)설정 시트'!$B$2, $D$1, 1), 0)), "", TEXT( DATE('(필수)설정 시트'!$B$2, $D$1, 1) + (COLUMN()-COLUMN($W$6)+2) + 7*INT((ROW()-ROW($W$6))/3) - WEEKDAY(DATE('(필수)설정 시트'!$B$2, $D$1, 1), 1) - 1, "d" ) ) )
C17: ='(필수)설정 시트'!C26 | D17: 0 | E17: 0 | M17: =M16-J17 | O17: ='(필수)설정 시트'!E42 | P17: 🚇지하철비 | Q17: =SUMIF($I$6:$I$56,P17,$J$6:$J$56) | T17: 🧑‍🤝‍🧑지인 | U17: =SUMIF($I$6:$I$56,T17,$J$6:$J$56) | W17: =IFERROR(SUMIF($G$6:$G$56, W16, $J$6:$J$56), "") | X17: =IFERROR(SUMIF($G$6:$G$56, X16, $J$6:$J$56), "") | Y17: =IFERROR(SUMIF($G$6:$G$56, Y16, $J$6:$J$56), "") | Z17: =IFERROR(SUMIF($G$6:$G$56, Z16, $J$6:$J$56), "") | AA17: =IFERROR(SUMIF($G$6:$G$56, AA16, $J$6:$J$56), "") | AB17: =IFERROR(SUMIF($G$6:$G$56, AB16, $J$6:$J$56), "") | AC17: =IFERROR(SUMIF($G$6:$G$56, AC16, $J$6:$J$56), "")
C18: ='(필수)설정 시트'!C27 | D18: 0 | E18: 0 | M18: =M17-J18 | P18: 🚕택시비 | Q18: =SUMIF($I$6:$I$56,P18,$J$6:$J$56) | U18: =SUMIF($I$6:$I$56,T18,$J$6:$J$56)
C19: ='(필수)설정 시트'!C28 | D19: 0 | E19: 0 | M19: =M18-J19 | P19: 🅿️주차비 | Q19: =SUMIF($I$6:$I$56,P19,$J$6:$J$56) | U19: =SUMIF($I$6:$I$56,T19,$J$6:$J$56) | W19: =IF( (COLUMN()-COLUMN($W$6)+2) + 7*INT((ROW()-ROW($W$6))/3) - WEEKDAY(DATE('(필수)설정 시트'!$B$2, $D$1, 1), 1) <= 0, "", IF( (COLUMN()-COLUMN($W$6)+2) + 7*INT((ROW()-ROW($W$6))/3) - WEEKDAY(DATE('(필수)설정 시트'!$B$2, $D$1, 1), 1) > DAY(EOMONTH(DATE('(필수)설정 시트'!$B$2, $D$1, 1), 0)), "", TEXT( DATE('(필수)설정 시트'!$B$2, $D$1, 1) + (COLUMN()-COLUMN($W$6)+2) + 7*INT((ROW()-ROW($W$6))/3) - WEEKDAY(DATE('(필수)설정 시트'!$B$2, $D$1, 1), 1) - 1, "d" ) ) ) | X19: =IF( (COLUMN()-COLUMN($W$6)+2) + 7*INT((ROW()-ROW($W$6))/3) - WEEKDAY(DATE('(필수)설정 시트'!$B$2, $D$1, 1), 1) <= 0, "", IF( (COLUMN()-COLUMN($W$6)+2) + 7*INT((ROW()-ROW($W$6))/3) - WEEKDAY(DATE('(필수)설정 시트'!$B$2, $D$1, 1), 1) > DAY(EOMONTH(DATE('(필수)설정 시트'!$B$2, $D$1, 1), 0)), "", TEXT( DATE('(필수)설정 시트'!$B$2, $D$1, 1) + (COLUMN()-COLUMN($W$6)+2) + 7*INT((ROW()-ROW($W$6))/3) - WEEKDAY(DATE('(필수)설정 시트'!$B$2, $D$1, 1), 1) - 1, "d" ) ) ) | Y19: =IF( (COLUMN()-COLUMN($W$6)+2) + 7*INT((ROW()-ROW($W$6))/3) - WEEKDAY(DATE('(필수)설정 시트'!$B$2, $D$1, 1), 1) <= 0, "", IF( (COLUMN()-COLUMN($W$6)+2) + 7*INT((ROW()-ROW($W$6))/3) - WEEKDAY(DATE('(필수)설정 시트'!$B$2, $D$1, 1), 1) > DAY(EOMONTH(DATE('(필수)설정 시트'!$B$2, $D$1, 1), 0)), "", TEXT( DATE('(필수)설정 시트'!$B$2, $D$1, 1) + (COLUMN()-COLUMN($W$6)+2) + 7*INT((ROW()-ROW($W$6))/3) - WEEKDAY(DATE('(필수)설정 시트'!$B$2, $D$1, 1), 1) - 1, "d" ) ) ) | Z19: =IF( (COLUMN()-COLUMN($W$6)+2) + 7*INT((ROW()-ROW($W$6))/3) - WEEKDAY(DATE('(필수)설정 시트'!$B$2, $D$1, 1), 1) <= 0, "", IF( (COLUMN()-COLUMN($W$6)+2) + 7*INT((ROW()-ROW($W$6))/3) - WEEKDAY(DATE('(필수)설정 시트'!$B$2, $D$1, 1), 1) > DAY(EOMONTH(DATE('(필수)설정 시트'!$B$2, $D$1, 1), 0)), "", TEXT( DATE('(필수)설정 시트'!$B$2, $D$1, 1) + (COLUMN()-COLUMN($W$6)+2) + 7*INT((ROW()-ROW($W$6))/3) - WEEKDAY(DATE('(필수)설정 시트'!$B$2, $D$1, 1), 1) - 1, "d" ) ) ) | AA19: =IF( (COLUMN()-COLUMN($W$6)+2) + 7*INT((ROW()-ROW($W$6))/3) - WEEKDAY(DATE('(필수)설정 시트'!$B$2, $D$1, 1), 1) <= 0, "", IF( (COLUMN()-COLUMN($W$6)+2) + 7*INT((ROW()-ROW($W$6))/3) - WEEKDAY(DATE('(필수)설정 시트'!$B$2, $D$1, 1), 1) > DAY(EOMONTH(DATE('(필수)설정 시트'!$B$2, $D$1, 1), 0)), "", TEXT( DATE('(필수)설정 시트'!$B$2, $D$1, 1) + (COLUMN()-COLUMN($W$6)+2) + 7*INT((ROW()-ROW($W$6))/3) - WEEKDAY(DATE('(필수)설정 시트'!$B$2, $D$1, 1), 1) - 1, "d" ) ) ) | AB19: =IF( (COLUMN()-COLUMN($W$6)+2) + 7*INT((ROW()-ROW($W$6))/3) - WEEKDAY(DATE('(필수)설정 시트'!$B$2, $D$1, 1), 1) <= 0, "", IF( (COLUMN()-COLUMN($W$6)+2) + 7*INT((ROW()-ROW($W$6))/3) - WEEKDAY(DATE('(필수)설정 시트'!$B$2, $D$1, 1), 1) > DAY(EOMONTH(DATE('(필수)설정 시트'!$B$2, $D$1, 1), 0)), "", TEXT( DATE('(필수)설정 시트'!$B$2, $D$1, 1) + (COLUMN()-COLUMN($W$6)+2) + 7*INT((ROW()-ROW($W$6))/3) - WEEKDAY(DATE('(필수)설정 시트'!$B$2, $D$1, 1), 1) - 1, "d" ) ) ) | AC19: =IF( (COLUMN()-COLUMN($W$6)+2) + 7*INT((ROW()-ROW($W$6))/3) - WEEKDAY(DATE('(필수)설정 시트'!$B$2, $D$1, 1), 1) <= 0, "", IF( (COLUMN()-COLUMN($W$6)+2) + 7*INT((ROW()-ROW($W$6))/3) - WEEKDAY(DATE('(필수)설정 시트'!$B$2, $D$1, 1), 1) > DAY(EOMONTH(DATE('(필수)설정 시트'!$B$2, $D$1, 1), 0)), "", TEXT( DATE('(필수)설정 시트'!$B$2, $D$1, 1) + (COLUMN()-COLUMN($W$6)+2) + 7*INT((ROW()-ROW($W$6))/3) - WEEKDAY(DATE('(필수)설정 시트'!$B$2, $D$1, 1), 1) - 1, "d" ) ) )
B20: 총 수입 | E20: =SUM(E15:E19) | M20: =M19-J20 | P20: ⛽주유비 | Q20: =SUMIF($I$6:$I$56,P20,$J$6:$J$56) | S20: ='(필수)설정 시트'!E47 | U20: =SUM(U13:U19) | W20: =IFERROR(SUMIF($G$6:$G$56, W19, $J$6:$J$56), "") | X20: =IFERROR(SUMIF($G$6:$G$56, X19, $J$6:$J$56), "") | Y20: =IFERROR(SUMIF($G$6:$G$56, Y19, $J$6:$J$56), "") | Z20: =IFERROR(SUMIF($G$6:$G$56, Z19, $J$6:$J$56), "") | AA20: =IFERROR(SUMIF($G$6:$G$56, AA19, $J$6:$J$56), "") | AB20: =IFERROR(SUMIF($G$6:$G$56, AB19, $J$6:$J$56), "") | AC20: =IFERROR(SUMIF($G$6:$G$43, AC19, $J$6:$J$43), "")
B21: 저축 | C21: 분류 | D21: 목표금액 | E21: 합계 | F21: 보험료 고정 | M21: =M20-J21 | Q21: =SUMIF($I$6:$I$56,P21,$J$6:$J$56) | S21: ='(필수)설정 시트'!E48 | T21: 🧧명절 | U21: =SUMIF($I$6:$I$56,T21,$J$6:$J$56)
C22: ='(필수)설정 시트'!F5 | D22: 0 | E22: 0 | M22: =M21-J22 | Q22: =SUMIF($I$6:$I$56,P22,$J$6:$J$56) | U22: =SUMIF($I$6:$I$56,T22,$J$6:$J$56)
D23: 0 | E23: 0 | M23: =M22-J23 | O23: ='(필수)설정 시트'!E42 | Q23: =SUM(Q17:Q22) | U23: =SUMIF($I$6:$I$56,T23,$J$6:$J$56)
D24: 0 | E24: 0 | M24: =M23-J24 | O24: ='(필수)설정 시트'!E43 | P24: ☕간식/카페 | Q24: =SUMIF($I$6:$I$56,P24,$J$6:$J$56) | U24: =SUMIF($I$6:$I$56,T24,$J$6:$J$56)
C25: ='(필수)설정 시트'!F8 | D25: 0 | E25: 0 | M25: =M24-J25 | P25: 🍽️외식 | Q25: =SUMIF($I$6:$I$56,P25,$J$6:$J$56) | U25: =SUMIF($I$6:$I$56,T25,$J$6:$J$56)
C26: ='(필수)설정 시트'!F9 | D26: 0 | E26: 0 | M26: =M25-J26 | P26: 🍱식재료비 | Q26: =SUMIF($I$6:$I$56,P26,$J$6:$J$56) | U26: =SUMIF($I$6:$I$56,T26,$J$6:$J$56)
C27: ='(필수)설정 시트'!F10 | D27: 0 | E27: 0 | M27: =M26-J27 | P27: 🌅아침 | Q27: =SUMIF($I$6:$I$56,P27,$J$6:$J$56) | S27: ='(필수)설정 시트'!E48 | U27: =SUM(U21:U26)
C28: ='(필수)설정 시트'!F11 | D28: 0 | E28: 0 | M28: =M27-J28 | P28: 🍛점심 | Q28: =SUMIF($I$6:$I$56,P28,$J$6:$J$56) | S28: ='(필수)설정 시트'!E49 | T28: 🏥병원 | U28: =SUMIF($I$6:$I$56,T28,$J$6:$J$56)
C29: ='(필수)설정 시트'!F12 | D29: 0 | E29: 0 | M29: =M28-J29 | P29: 🌙저녁 | Q29: =SUMIF($I$6:$I$56,P29,$J$6:$J$56) | T29: 💊약국 | U29: =SUMIF($I$6:$I$56,T29,$J$6:$J$56)
C30: ='(필수)설정 시트'!F13 | D30: 0 | E30: 0 | M30: =M29-J30 | P30: 🛵배달 | Q30: =SUMIF($I$6:$I$56,P30,$J$6:$J$56) | T30: 💊영양제 | U30: =SUMIF($I$6:$I$56,T30,$J$6:$J$56)
C31: ='(필수)설정 시트'!F14 | D31: 0 | E31: 0 | M31: =M30-J31 | O31: ='(필수)설정 시트'!E43 | Q31: =SUM(Q24:Q30) | U31: =SUMIF($I$6:$I$56,T31,$J$6:$J$56)
C32: ='(필수)설정 시트'!F15 | D32: 0 | E32: 0 | M32: =M31-J32 | O32: ='(필수)설정 시트'!E44 | P32: 🎓강의 | Q32: =SUMIF($I$6:$I$56,P32,$J$6:$J$56) | U32: =SUMIF($I$6:$I$56,T32,$J$6:$J$56)
C33: ='(필수)설정 시트'!F16 | D33: 0 | E33: 0 | M33: =M32-J33 | P33: 🪪자격증 | Q33: =SUMIF($I$6:$I$56,P33,$J$6:$J$56) | U33: =SUMIF($I$6:$I$56,T33,$J$6:$J$56)
B34: 총 저축 | E34: =SUM(E22:E33) | M34: =M33-J34 | P34: 📚도서 | Q34: =SUMIF($I$6:$I$56,P34,$J$6:$J$56) | S34: ='(필수)설정 시트'!E49 | U34: =SUM(U28:U33)
M35: =M34-J35 | P35: 🤖AI | Q35: =SUMIF($I$6:$I$56,P35,$J$6:$J$56) | S35: ='(필수)설정 시트'!E50 | T35: 💸축의금 | U35: =SUMIF($I$6:$I$56,T35,$J$6:$J$56)
M36: =M35-J36 | Q36: =SUMIF($I$6:$I$56,P36,$J$6:$J$56) | T36: 🖤부의금 | U36: =SUMIF($I$6:$I$56,T36,$J$6:$J$56)
M37: =M36-J37 | Q37: =SUMIF($I$6:$I$56,P37,$J$6:$J$56) | U37: =SUMIF($I$6:$I$56,T37,$J$6:$J$56)
M38: =M37-J38 | O38: ='(필수)설정 시트'!E44 | Q38: =SUM(Q32:Q37) | U38: =SUMIF($I$6:$I$56,T38,$J$6:$J$56)
M39: =M38-J39 | O39: ='(필수)설정 시트'!E45 | P39: 🎭문화생활 | Q39: =SUMIF($I$6:$I$56,P39,$J$6:$J$56) | U39: =SUMIF($I$6:$I$56,T39,$J$6:$J$56)
M40: =M39-J40 | P40: ✈️여행 | Q40: =SUMIF($I$6:$I$56,P40,$J$6:$J$56) | U40: =SUMIF($I$6:$I$56,T40,$J$6:$J$56)
...

Sheet 3월
D1: 1
B2: ='(필수)설정 시트'!B2 | F2: 총 수입 | H2: 총 저축 | J2: 총 지출 비용 | L2: 남은 잔액(부수입 제외)
F3: =C6 | H3: =C8 | J3: =C7 | L3: =(C6-E18)-C7-C8
H4: 항목 변경 시 데이터 확인 규칙 변경 필요
B5: 분류 | C5: 금액 | D5: 결제수단 | E5: 금액 | G5: 날짜[숫자만 입력] | H5: 대분류 | I5: 소분류 | J5: 금액 | K5: 결제수단 | L5: 세부사항 | M5: 남은 잔액 | O5: 대분류 | P5: 소분류 | Q5: 지출금액 | S5: 대분류 | T5: 소분류 | U5: 지출금액 | W5: 일 | X5: 월 | Y5: 화 | Z5: 수 | AA5: 목 | AB5: 금 | AC5: 토
B6: 총 수입 | C6: =E20 | M6: =$E$20-J6 | O6: ='(필수)설정 시트'!E41 | P6: 📱통신비 | Q6: =SUMIF($I$6:$I$56,P6,$J$6:$J$56) | S6: ='(필수)설정 시트'!E46 | T6: 👕의류 | U6: =SUMIF($I$6:$I$56,T6,$J$6:$J$56) | W6: =IF( (COLUMN()-COLUMN($W$6)+2) + 7*INT((ROW()-ROW($W$6))/3) - WEEKDAY(DATE('(필수)설정 시트'!$B$2, $D$1, 1), 1) <= 0, "", IF( (COLUMN()-COLUMN($W$6)+2) + 7*INT((ROW()-ROW($W$6))/3) - WEEKDAY(DATE('(필수)설정 시트'!$B$2, $D$1, 1), 1) > DAY(EOMONTH(DATE('(필수)설정 시트'!$B$2, $D$1, 1), 0)), "", TEXT( DATE('(필수)설정 시트'!$B$2, $D$1, 1) + (COLUMN()-COLUMN($W$6)+2) + 7*INT((ROW()-ROW($W$6))/3) - WEEKDAY(DATE('(필수)설정 시트'!$B$2, $D$1, 1), 1) - 1, "d" ) ) ) | X6: =IF( (COLUMN()-COLUMN($W$6)+2) + 7*INT((ROW()-ROW($W$6))/3) - WEEKDAY(DATE('(필수)설정 시트'!$B$2, $D$1, 1), 1) <= 0, "", IF( (COLUMN()-COLUMN($W$6)+2) + 7*INT((ROW()-ROW($W$6))/3) - WEEKDAY(DATE('(필수)설정 시트'!$B$2, $D$1, 1), 1) > DAY(EOMONTH(DATE('(필수)설정 시트'!$B$2, $D$1, 1), 0)), "", TEXT( DATE('(필수)설정 시트'!$B$2, $D$1, 1) + (COLUMN()-COLUMN($W$6)+2) + 7*INT((ROW()-ROW($W$6))/3) - WEEKDAY(DATE('(필수)설정 시트'!$B$2, $D$1, 1), 1) - 1, "d" ) ) ) | Y6: =IF( (COLUMN()-COLUMN($W$6)+2) + 7*INT((ROW()-ROW($W$6))/3) - WEEKDAY(DATE('(필수)설정 시트'!$B$2, $D$1, 1), 1) <= 0, "", IF( (COLUMN()-COLUMN($W$6)+2) + 7*INT((ROW()-ROW($W$6))/3) - WEEKDAY(DATE('(필수)설정 시트'!$B$2, $D$1, 1), 1) > DAY(EOMONTH(DATE('(필수)설정 시트'!$B$2, $D$1, 1), 0)), "", TEXT( DATE('(필수)설정 시트'!$B$2, $D$1, 1) + (COLUMN()-COLUMN($W$6)+2) + 7*INT((ROW()-ROW($W$6))/3) - WEEKDAY(DATE('(필수)설정 시트'!$B$2, $D$1, 1), 1) - 1, "d" ) ) ) | Z6: =IF( (COLUMN()-COLUMN($W$6)+2) + 7*INT((ROW()-ROW($W$6))/3) - WEEKDAY(DATE('(필수)설정 시트'!$B$2, $D$1, 1), 1) <= 0, "", IF( (COLUMN()-COLUMN($W$6)+2) + 7*INT((ROW()-ROW($W$6))/3) - WEEKDAY(DATE('(필수)설정 시트'!$B$2, $D$1, 1), 1) > DAY(EOMONTH(DATE('(필수)설정 시트'!$B$2, $D$1, 1), 0)), "", TEXT( DATE('(필수)설정 시트'!$B$2, $D$1, 1) + (COLUMN()-COLUMN($W$6)+2) + 7*INT((ROW()-ROW($W$6))/3) - WEEKDAY(DATE('(필수)설정 시트'!$B$2, $D$1, 1), 1) - 1, "d" ) ) ) | AA6: =IF( (COLUMN()-COLUMN($W$6)+2) + 7*INT((ROW()-ROW($W$6))/3) - WEEKDAY(DATE('(필수)설정 시트'!$B$2, $D$1, 1), 1) <= 0, "", IF( (COLUMN()-COLUMN($W$6)+2) + 7*INT((ROW()-ROW($W$6))/3) - WEEKDAY(DATE('(필수)설정 시트'!$B$2, $D$1, 1), 1) > DAY(EOMONTH(DATE('(필수)설정 시트'!$B$2, $D$1, 1), 0)), "", TEXT( DATE('(필수)설정 시트'!$B$2, $D$1, 1) + (COLUMN()-COLUMN($W$6)+2) + 7*INT((ROW()-ROW($W$6))/3) - WEEKDAY(DATE('(필수)설정 시트'!$B$2, $D$1, 1), 1) - 1, "d" ) ) ) | AB6: =IF( (COLUMN()-COLUMN($W$6)+2) + 7*INT((ROW()-ROW($W$6))/3) - WEEKDAY(DATE('(필수)설정 시트'!$B$2, $D$1, 1), 1) <= 0, "", IF( (COLUMN()-COLUMN($W$6)+2) + 7*INT((ROW()-ROW($W$6))/3) - WEEKDAY(DATE('(필수)설정 시트'!$B$2, $D$1, 1), 1) > DAY(EOMONTH(DATE('(필수)설정 시트'!$B$2, $D$1, 1), 0)), "", TEXT( DATE('(필수)설정 시트'!$B$2, $D$1, 1) + (COLUMN()-COLUMN($W$6)+2) + 7*INT((ROW()-ROW($W$6))/3) - WEEKDAY(DATE('(필수)설정 시트'!$B$2, $D$1, 1), 1) - 1, "d" ) ) ) | AC6: =IF( (COLUMN()-COLUMN($W$6)+2) + 7*INT((ROW()-ROW($W$6))/3) - WEEKDAY(DATE('(필수)설정 시트'!$B$2, $D$1, 1), 1) <= 0, "", IF( (COLUMN()-COLUMN($W$6)+2) + 7*INT((ROW()-ROW($W$6))/3) - WEEKDAY(DATE('(필수)설정 시트'!$B$2, $D$1, 1), 1) > DAY(EOMONTH(DATE('(필수)설정 시트'!$B$2, $D$1, 1), 0)), "", TEXT( DATE('(필수)설정 시트'!$B$2, $D$1, 1) + (COLUMN()-COLUMN($W$6)+2) + 7*INT((ROW()-ROW($W$6))/3) - WEEKDAY(DATE('(필수)설정 시트'!$B$2, $D$1, 1), 1) - 1, "d" ) ) )
B7: 총 지출 | C7: =SUM($J$6:$J$56) - E34 | M7: =M6-J7 | P7: 🚍교통비 | Q7: =SUMIF($I$6:$I$56,P7,$J$6:$J$56) | T7: 💇미용 | U7: =SUMIF($I$6:$I$56,T7,$J$6:$J$56) | W7: =IFERROR(SUMIF($G$6:$G$56, W6, $J$6:$J$56), "") | X7: =IFERROR(SUMIF($G$6:$G$56, X6, $J$6:$J$56), "") | Y7: =IFERROR(SUMIF($G$6:$G$56, Y6, $J$6:$J$56), "") | Z7: =IFERROR(SUMIF($G$6:$G$56, Z6, $J$6:$J$56), "") | AA7: =IFERROR(SUMIF($G$6:$G$56, AA6, $J$6:$J$56), "") | AB7: =IFERROR(SUMIF($G$6:$G$56, AB6, $J$6:$J$56), "") | AC7: =IFERROR(SUMIF($G$6:$G$56, AC6, $J$6:$J$56), "")
B8: 총 저축 | C8: =E34 | M8: =M7-J8 | P8: 📺스트리밍 서비스 | Q8: =SUMIF($I$6:$I$56,P8,$J$6:$J$56) | T8: 💬잡화 | U8: =SUMIF($I$6:$I$56,T8,$J$6:$J$56)
B9: 총 저축률 | C9: =C8/C6 | M9: =M8-J9 | P9: 🎵멜론 | Q9: =SUMIF($I$6:$I$56,P9,$J$6:$J$56) | U9: =SUMIF($I$6:$I$56,T9,$J$6:$J$56) | W9: =IF( (COLUMN()-COLUMN($W$6)+2) + 7*INT((ROW()-ROW($W$6))/3) - WEEKDAY(DATE('(필수)설정 시트'!$B$2, $D$1, 1), 1) <= 0, "", IF( (COLUMN()-COLUMN($W$6)+2) + 7*INT((ROW()-ROW($W$6))/3) - WEEKDAY(DATE('(필수)설정 시트'!$B$2, $D$1, 1), 1) > DAY(EOMONTH(DATE('(필수)설정 시트'!$B$2, $D$1, 1), 0)), "", TEXT( DATE('(필수)설정 시트'!$B$2, $D$1, 1) + (COLUMN()-COLUMN($W$6)+2) + 7*INT((ROW()-ROW($W$6))/3) - WEEKDAY(DATE('(필수)설정 시트'!$B$2, $D$1, 1), 1) - 1, "d" ) ) ) | X9: =IF( (COLUMN()-COLUMN($W$6)+2) + 7*INT((ROW()-ROW($W$6))/3) - WEEKDAY(DATE('(필수)설정 시트'!$B$2, $D$1, 1), 1) <= 0, "", IF( (COLUMN()-COLUMN($W$6)+2) + 7*INT((ROW()-ROW($W$6))/3) - WEEKDAY(DATE('(필수)설정 시트'!$B$2, $D$1, 1), 1) > DAY(EOMONTH(DATE('(필수)설정 시트'!$B$2, $D$1, 1), 0)), "", TEXT( DATE('(필수)설정 시트'!$B$2, $D$1, 1) + (COLUMN()-COLUMN($W$6)+2) + 7*INT((ROW()-ROW($W$6))/3) - WEEKDAY(DATE('(필수)설정 시트'!$B$2, $D$1, 1), 1) - 1, "d" ) ) ) | Y9: =IF( (COLUMN()-COLUMN($W$6)+2) + 7*INT((ROW()-ROW($W$6))/3) - WEEKDAY(DATE('(필수)설정 시트'!$B$2, $D$1, 1), 1) <= 0, "", IF( (COLUMN()-COLUMN($W$6)+2) + 7*INT((ROW()-ROW($W$6))/3) - WEEKDAY(DATE('(필수)설정 시트'!$B$2, $D$1, 1), 1) > DAY(EOMONTH(DATE('(필수)설정 시트'!$B$2, $D$1, 1), 0)), "", TEXT( DATE('(필수)설정 시트'!$B$2, $D$1, 1) + (COLUMN()-COLUMN($W$6)+2) + 7*INT((ROW()-ROW($W$6))/3) - WEEKDAY(DATE('(필수)설정 시트'!$B$2, $D$1, 1), 1) - 1, "d" ) ) ) | Z9: =IF( (COLUMN()-COLUMN($W$6)+2) + 7*INT((ROW()-ROW($W$6))/3) - WEEKDAY(DATE('(필수)설정 시트'!$B$2, $D$1, 1), 1) <= 0, "", IF( (COLUMN()-COLUMN($W$6)+2) + 7*INT((ROW()-ROW($W$6))/3) - WEEKDAY(DATE('(필수)설정 시트'!$B$2, $D$1, 1), 1) > DAY(EOMONTH(DATE('(필수)설정 시트'!$B$2, $D$1, 1), 0)), "", TEXT( DATE('(필수)설정 시트'!$B$2, $D$1, 1) + (COLUMN()-COLUMN($W$6)+2) + 7*INT((ROW()-ROW($W$6))/3) - WEEKDAY(DATE('(필수)설정 시트'!$B$2, $D$1, 1), 1) - 1, "d" ) ) ) | AA9: =IF( (COLUMN()-COLUMN($W$6)+2) + 7*INT((ROW()-ROW($W$6))/3) - WEEKDAY(DATE('(필수)설정 시트'!$B$2, $D$1, 1), 1) <= 0, "", IF( (COLUMN()-COLUMN($W$6)+2) + 7*INT((ROW()-ROW($W$6))/3) - WEEKDAY(DATE('(필수)설정 시트'!$B$2, $D$1, 1), 1) > DAY(EOMONTH(DATE('(필수)설정 시트'!$B$2, $D$1, 1), 0)), "", TEXT( DATE('(필수)설정 시트'!$B$2, $D$1, 1) + (COLUMN()-COLUMN($W$6)+2) + 7*INT((ROW()-ROW($W$6))/3) - WEEKDAY(DATE('(필수)설정 시트'!$B$2, $D$1, 1), 1) - 1, "d" ) ) ) | AB9: =IF( (COLUMN()-COLUMN($W$6)+2) + 7*INT((ROW()-ROW($W$6))/3) - WEEKDAY(DATE('(필수)설정 시트'!$B$2, $D$1, 1), 1) <= 0, "", IF( (COLUMN()-COLUMN($W$6)+2) + 7*INT((ROW()-ROW($W$6))/3) - WEEKDAY(DATE('(필수)설정 시트'!$B$2, $D$1, 1), 1) > DAY(EOMONTH(DATE('(필수)설정 시트'!$B$2, $D$1, 1), 0)), "", TEXT( DATE('(필수)설정 시트'!$B$2, $D$1, 1) + (COLUMN()-COLUMN($W$6)+2) + 7*INT((ROW()-ROW($W$6))/3) - WEEKDAY(DATE('(필수)설정 시트'!$B$2, $D$1, 1), 1) - 1, "d" ) ) ) | AC9: =IF( (COLUMN()-COLUMN($W$6)+2) + 7*INT((ROW()-ROW($W$6))/3) - WEEKDAY(DATE('(필수)설정 시트'!$B$2, $D$1, 1), 1) <= 0, "", IF( (COLUMN()-COLUMN($W$6)+2) + 7*INT((ROW()-ROW($W$6))/3) - WEEKDAY(DATE('(필수)설정 시트'!$B$2, $D$1, 1), 1) > DAY(EOMONTH(DATE('(필수)설정 시트'!$B$2, $D$1, 1), 0)), "", TEXT( DATE('(필수)설정 시트'!$B$2, $D$1, 1) + (COLUMN()-COLUMN($W$6)+2) + 7*INT((ROW()-ROW($W$6))/3) - WEEKDAY(DATE('(필수)설정 시트'!$B$2, $D$1, 1), 1) - 1, "d" ) ) )
B10: 보유 현금 | M10: =M9-J10 | P10: 🛡️보험료 | Q10: =SUMIF($I$6:$I$56,P10,$J$6:$J$56) | U10: =SUMIF($I$6:$I$56,T10,$J$6:$J$56) | W10: =IFERROR(SUMIF($G$6:$G$56, W9, $J$6:$J$56), "") | X10: =IFERROR(SUMIF($G$6:$G$56, X9, $J$6:$J$56), "") | Y10: =IFERROR(SUMIF($G$6:$G$56, Y9, $J$6:$J$56), "") | Z10: =IFERROR(SUMIF($G$6:$G$56, Z9, $J$6:$J$56), "") | AA10: =IFERROR(SUMIF($G$6:$G$56, AA9, $J$6:$J$56), "") | AB10: =IFERROR(SUMIF($G$6:$G$56, AB9, $J$6:$J$56), "") | AC10: =IFERROR(SUMIF($G$6:$G$56, AC9, $J$6:$J$56), "")
B11: 월급에 대한 저축률 | C11: =C8/E15 | M11: =M10-J11 | P11: 🏠생활비 | Q11: =SUMIF($I$6:$I$56,P11,$J$6:$J$56) | U11: =SUMIF($I$6:$I$56,T11,$J$6:$J$56)
